<?xml version="1.0"?>
<robot xmlns:xacro="http://www.ros.org/wiki/xacro" name="robot">
    
    <xacro:include filename="inertial_macros.xacro"/>

    <material name="light_blue">
      <color rgba="0.65 0.83 0.96 1"/>
    </material>   

    <material name="orange">
      <color rgba="1 0.3 0.1 1"/>
    </material>

    <material name="blue">
      <color rgba="0.2 0.2 1 1"/>
    </material>    
    
    <material name="black">
      <color rgba="0 0 0 1"/>
    </material>

    <!-- BASE LINK -->
    <link name="base_link">
    </link>

    <!-- CHASSIS -->
    <joint name="chassis_joint" type="fixed">
      <parent link="base_link"/>
      <child link="chassis"/>
      <origin xyz="0 0 0.25"/>
    </joint>

    <link name="chassis">
      <visual>
        <origin xyz="0 0 0"/>
        <geometry>
          <cylinder radius="0.5" length="0.5"/>
        </geometry>
        <material name="light_blue"/>
      </visual>
      <collision>
        <origin xyz="0 0 0"/>
        <geometry>
          <cylinder radius="0.5" length="0.5"/>
        </geometry>
      </collision>
      <xacro:inertial_cylinder mass="40.0" length="0.5" radius="0.5">
        <origin xyz="0 0 0" rpy= "0 0 0"/> 
      </xacro:inertial_cylinder>
    </link>

    <gazebo reference="chassis">
      <material>Gazebo/Blue</material> 
    </gazebo>  

    <!-- LEFT WHEEL -->
    <joint name="left_wheel_joint" type="continuous">
      <parent link="base_link"/>
      <child link="left_wheel"/>
      <origin xyz="0 0.35 0" rpy="-${pi/2} 0 0"/> 
      <axis xyz="0 0 1"/>
    </joint>

    <link name="left_wheel">
      <visual>
        <geometry>
          <cylinder radius="0.05" length="0.04"/>
        </geometry>
        <material name="black"/>
      </visual>
      <collision>
        <geometry>
          <cylinder radius="0.05" length="0.04"/>
        </geometry>
      </collision>
      <xacro:inertial_cylinder mass="1.0" length="0.04" radius="0.05">
        <origin xyz="0 0 0" rpy="0 0 0"/>
      </xacro:inertial_cylinder>
    </link>

    <gazebo reference="left_wheel">
      <material>Gazebo/Black</material>
    </gazebo>


    <!-- RIGHT WHEEL -->
    <joint name="right_wheel_joint" type="continuous">
      <parent link="base_link"/>
      <child link="right_wheel"/>
      <origin xyz="0 -0.35 0" rpy="${pi/2} 0 0"/> 
      <axis xyz="0 0 -1"/>
    </joint>

    <link name="right_wheel">
      <visual>
        <geometry>
          <cylinder radius="0.05" length="0.04"/>
        </geometry>
        <material name="black"/>
      </visual>
      <collision>
        <geometry>
          <cylinder radius="0.05" length="0.04"/>
        </geometry>
      </collision>
      <xacro:inertial_cylinder mass="1.0" length="0.04" radius="0.05">
        <origin xyz="0 0 0" rpy="0 0 0"/>
      </xacro:inertial_cylinder>
    </link>

    <gazebo reference="right_wheel">
      <material>Gazebo/Black</material>
    </gazebo>


    <!-- CASTER WHEEL 1-->
    <joint name ="caster_wheel_1_joint" type="fixed">
      <parent link="chassis"/>
      <child link="caster_wheel_1"/>
      <origin xyz="0.35 0 -0.25"/> 
    </joint> 

    <link name="caster_wheel_1">
      <visual>
        <geometry>
          <sphere radius="0.05"/>
        </geometry>
        <material name="orange"/> 
      </visual>
      <collision>
        <geometry>
          <sphere radius="0.05"/>
        </geometry>
      </collision>
      <xacro:inertial_sphere mass="0.1" radius="0.04">
        <origin xyz="0 0 0" rpy="0 0 0"/>
      </xacro:inertial_sphere>
    </link> 

    <gazebo reference="caster_wheel_1">
      <material>Gazebo/Orange</material>
      <mu1 value="0.001"/>
      <mu2 value="0.002"/>
    </gazebo>

    <!-- CASTER WHEEL 2-->
    <joint name ="caster_wheel_2_joint" type="fixed">
      <parent link="chassis"/>
      <child link="caster_wheel_2"/>
      <origin xyz="-0.35 0 -0.25"/> 
    </joint> 

    <link name="caster_wheel_2">
      <visual>
        <geometry>
          <sphere radius="0.05"/>
        </geometry>
        <material name="orange"/> 
      </visual>
      <collision>
        <geometry>
          <sphere radius="0.05"/>
        </geometry>
      </collision>
      <xacro:inertial_sphere mass="0.1" radius="0.04">
        <origin xyz="0 0 0" rpy="0 0 0"/>
      </xacro:inertial_sphere>
    </link> 

    <gazebo reference="caster_wheel_2">
      <material>Gazebo/Orange</material>
      <mu1 value="0.001"/>
      <mu2 value="0.001"/>
    </gazebo>

</robot>