<sdf version='1.7'>
  <world name='default'>
    <light name='sun' type='directional'>
      <cast_shadows>1</cast_shadows>
      <pose>0 0 10 0 -0 0</pose>
      <diffuse>0.8 0.8 0.8 1</diffuse>
      <specular>0.2 0.2 0.2 1</specular>
      <attenuation>
        <range>1000</range>
        <constant>0.9</constant>
        <linear>0.01</linear>
        <quadratic>0.001</quadratic>
      </attenuation>
      <direction>-0.5 0.1 -0.9</direction>
      <spot>
        <inner_angle>0</inner_angle>
        <outer_angle>0</outer_angle>
        <falloff>0</falloff>
      </spot>
    </light>
    <model name='ground_plane'>
      <static>1</static>
      <link name='link'>
        <collision name='collision'>
          <geometry>
            <plane>
              <normal>0 0 1</normal>
              <size>100 100</size>
            </plane>
          </geometry>
          <surface>
            <contact>
              <collide_bitmask>65535</collide_bitmask>
              <ode/>
            </contact>
            <friction>
              <ode>
                <mu>100</mu>
                <mu2>50</mu2>
              </ode>
              <torsional>
                <ode/>
              </torsional>
            </friction>
            <bounce/>
          </surface>
          <max_contacts>10</max_contacts>
        </collision>
        <visual name='visual'>
          <cast_shadows>0</cast_shadows>
          <geometry>
            <plane>
              <normal>0 0 1</normal>
              <size>100 100</size>
            </plane>
          </geometry>
          <material>
            <script>
              <uri>file://media/materials/scripts/gazebo.material</uri>
              <name>Gazebo/Grey</name>
            </script>
          </material>
        </visual>
        <self_collide>0</self_collide>
        <enable_wind>0</enable_wind>
        <kinematic>0</kinematic>
      </link>
    </model>
    <gravity>0 0 -9.8</gravity>
    <magnetic_field>6e-06 2.3e-05 -4.2e-05</magnetic_field>
    <atmosphere type='adiabatic'/>
    <physics type='ode'>
      <max_step_size>0.001</max_step_size>
      <real_time_factor>1</real_time_factor>
      <real_time_update_rate>1000</real_time_update_rate>
    </physics>
    <scene>
      <ambient>0.4 0.4 0.4 1</ambient>
      <background>0.7 0.7 0.7 1</background>
      <shadows>1</shadows>
    </scene>
    <wind/>
    <spherical_coordinates>
      <surface_model>EARTH_WGS84</surface_model>
      <latitude_deg>0</latitude_deg>
      <longitude_deg>0</longitude_deg>
      <elevation>0</elevation>
      <heading_deg>0</heading_deg>
    </spherical_coordinates>
    <model name='fire_hose_long'>
      <pose>0.523019 0.062878 10 0.708 -0 0</pose>
      <joint name='joint_01_world' type='revolute'>
        <child>nozzle</child>
        <parent>world</parent>
        <axis>
          <xyz expressed_in='__model__'>0.5 1 0.2</xyz>
          <dynamics>
            <damping>10</damping>
            <friction>0</friction>
            <spring_reference>0</spring_reference>
            <spring_stiffness>0</spring_stiffness>
          </dynamics>
          <limit>
            <lower>-1e+16</lower>
            <upper>1e+16</upper>
          </limit>
        </axis>
      </joint>
      <link name='nozzle'>
        <pose>0 0 0 0 -0 0</pose>
        <inertial>
          <pose>0 0 0 0 -0 0</pose>
          <mass>0.1</mass>
          <inertia>
            <ixx>0.01</ixx>
            <ixy>0</ixy>
            <ixz>0</ixz>
            <iyy>0.01</iyy>
            <iyz>0</iyz>
            <izz>0.01</izz>
          </inertia>
        </inertial>
        <collision name='nozzle_collision'>
          <pose>-0 0 0 0 -0 0</pose>
          <geometry>
            <mesh>
              <scale>0.00254 0.00254 0.00254</scale>
              <uri>model://fire_hose_long/meshes/nozzle.stl</uri>
            </mesh>
          </geometry>
          <max_contacts>10</max_contacts>
          <surface>
            <contact>
              <ode/>
            </contact>
            <bounce/>
            <friction>
              <torsional>
                <ode/>
              </torsional>
              <ode/>
            </friction>
          </surface>
        </collision>
        <visual name='nozzle_vis'>
          <pose>-0 0 0 0 -0 0</pose>
          <geometry>
            <mesh>
              <scale>0.00254 0.00254 0.00254</scale>
              <uri>model://fire_hose_long/meshes/nozzle.stl</uri>
            </mesh>
          </geometry>
        </visual>
        <velocity_decay/>
        <self_collide>0</self_collide>
        <enable_wind>0</enable_wind>
        <kinematic>0</kinematic>
      </link>
      <link name='sphere_01'>
        <gravity>0</gravity>
        <pose>0.1 0 0 0 -0 0</pose>
        <inertial>
          <pose>0 0 0 0 -0 0</pose>
          <mass>0.1</mass>
          <inertia>
            <ixx>0.01</ixx>
            <ixy>0</ixy>
            <ixz>0</ixz>
            <iyy>0.01</iyy>
            <iyz>0</iyz>
            <izz>0.01</izz>
          </inertia>
        </inertial>
        <collision name='sphere_01_collision'>
          <pose>0 0 0 0 -0 0</pose>
          <geometry>
            <sphere>
              <radius>0.025</radius>
            </sphere>
          </geometry>
          <max_contacts>10</max_contacts>
          <surface>
            <contact>
              <ode/>
            </contact>
            <bounce/>
            <friction>
              <torsional>
                <ode/>
              </torsional>
              <ode/>
            </friction>
          </surface>
        </collision>
        <visual name='sphere_01_vis'>
          <pose>0 0 0 0 -0 0</pose>
          <geometry>
            <sphere>
              <radius>0.025</radius>
            </sphere>
          </geometry>
        </visual>
        <velocity_decay/>
        <self_collide>0</self_collide>
        <enable_wind>0</enable_wind>
        <kinematic>0</kinematic>
      </link>
      <joint name='joint_01_1' type='revolute'>
        <child>sphere_01</child>
        <parent>nozzle</parent>
        <axis>
          <xyz expressed_in='__model__'>0 0 1</xyz>
          <limit>
            <lower>-0.7</lower>
            <upper>0.7</upper>
          </limit>
          <dynamics>
            <damping>10</damping>
            <friction>0</friction>
            <spring_reference>0</spring_reference>
            <spring_stiffness>0</spring_stiffness>
          </dynamics>
        </axis>
      </joint>
      <link name='link_01'>
        <gravity>0</gravity>
        <pose>0.1 0 0 0 -0 0</pose>
        <inertial>
          <pose>0 0 0 0 -0 0</pose>
          <mass>0.1</mass>
          <inertia>
            <ixx>0.01</ixx>
            <ixy>0</ixy>
            <ixz>0</ixz>
            <iyy>0.01</iyy>
            <iyz>0</iyz>
            <izz>0.01</izz>
          </inertia>
        </inertial>
        <collision name='link_01_collision'>
          <pose>0.1 0 0 0 1.57079 0</pose>
          <geometry>
            <cylinder>
              <length>0.2</length>
              <radius>0.025</radius>
            </cylinder>
          </geometry>
          <max_contacts>10</max_contacts>
          <surface>
            <contact>
              <ode/>
            </contact>
            <bounce/>
            <friction>
              <torsional>
                <ode/>
              </torsional>
              <ode/>
            </friction>
          </surface>
        </collision>
        <visual name='link_01_vis'>
          <pose>0.1 0 0 0 1.57079 0</pose>
          <geometry>
            <cylinder>
              <length>0.2</length>
              <radius>0.025</radius>
            </cylinder>
          </geometry>
        </visual>
        <velocity_decay/>
        <self_collide>0</self_collide>
        <enable_wind>0</enable_wind>
        <kinematic>0</kinematic>
      </link>
      <joint name='joint_01_2' type='revolute'>
        <child>link_01</child>
        <parent>sphere_01</parent>
        <axis>
          <xyz expressed_in='__model__'>0 1 0</xyz>
          <limit>
            <lower>-0.7</lower>
            <upper>0.7</upper>
          </limit>
          <dynamics>
            <damping>10</damping>
            <friction>0</friction>
            <spring_reference>0</spring_reference>
            <spring_stiffness>0</spring_stiffness>
          </dynamics>
        </axis>
      </joint>
      <link name='sphere_02'>
        <gravity>0</gravity>
        <pose>0.3 0 0 0 -0 0</pose>
        <inertial>
          <pose>0 0 0 0 -0 0</pose>
          <mass>0.1</mass>
          <inertia>
            <ixx>0.01</ixx>
            <ixy>0</ixy>
            <ixz>0</ixz>
            <iyy>0.01</iyy>
            <iyz>0</iyz>
            <izz>0.01</izz>
          </inertia>
        </inertial>
        <collision name='sphere_02_collision'>
          <pose>0 0 0 0 -0 0</pose>
          <geometry>
            <sphere>
              <radius>0.025</radius>
            </sphere>
          </geometry>
          <max_contacts>10</max_contacts>
          <surface>
            <contact>
              <ode/>
            </contact>
            <bounce/>
            <friction>
              <torsional>
                <ode/>
              </torsional>
              <ode/>
            </friction>
          </surface>
        </collision>
        <visual name='sphere_02_vis'>
          <pose>0 0 0 0 -0 0</pose>
          <geometry>
            <sphere>
              <radius>0.025</radius>
            </sphere>
          </geometry>
        </visual>
        <velocity_decay/>
        <self_collide>0</self_collide>
        <enable_wind>0</enable_wind>
        <kinematic>0</kinematic>
      </link>
      <joint name='joint_02_1' type='revolute'>
        <child>sphere_02</child>
        <parent>link_01</parent>
        <axis>
          <xyz expressed_in='__model__'>0 0 1</xyz>
          <limit>
            <lower>-0.7</lower>
            <upper>0.7</upper>
          </limit>
          <dynamics>
            <damping>10</damping>
            <friction>0</friction>
            <spring_reference>0</spring_reference>
            <spring_stiffness>0</spring_stiffness>
          </dynamics>
        </axis>
      </joint>
      <link name='link_02'>
        <gravity>0</gravity>
        <pose>0.3 0 0 0 -0 0</pose>
        <inertial>
          <pose>0 0 0 0 -0 0</pose>
          <mass>0.1</mass>
          <inertia>
            <ixx>0.01</ixx>
            <ixy>0</ixy>
            <ixz>0</ixz>
            <iyy>0.01</iyy>
            <iyz>0</iyz>
            <izz>0.01</izz>
          </inertia>
        </inertial>
        <collision name='link_02_collision'>
          <pose>0.1 0 0 0 1.57079 0</pose>
          <geometry>
            <cylinder>
              <length>0.2</length>
              <radius>0.025</radius>
            </cylinder>
          </geometry>
          <max_contacts>10</max_contacts>
          <surface>
            <contact>
              <ode/>
            </contact>
            <bounce/>
            <friction>
              <torsional>
                <ode/>
              </torsional>
              <ode/>
            </friction>
          </surface>
        </collision>
        <visual name='link_02_vis'>
          <pose>0.1 0 0 0 1.57079 0</pose>
          <geometry>
            <cylinder>
              <length>0.2</length>
              <radius>0.025</radius>
            </cylinder>
          </geometry>
        </visual>
        <velocity_decay/>
        <self_collide>0</self_collide>
        <enable_wind>0</enable_wind>
        <kinematic>0</kinematic>
      </link>
      <joint name='joint_02_2' type='revolute'>
        <child>link_02</child>
        <parent>sphere_02</parent>
        <axis>
          <xyz expressed_in='__model__'>0 1 0</xyz>
          <limit>
            <lower>-0.7</lower>
            <upper>0.7</upper>
          </limit>
          <dynamics>
            <damping>10</damping>
            <friction>0</friction>
            <spring_reference>0</spring_reference>
            <spring_stiffness>0</spring_stiffness>
          </dynamics>
        </axis>
      </joint>
      <link name='sphere_03'>
        <gravity>0</gravity>
        <pose>0.5 0 0 0 -0 0</pose>
        <inertial>
          <pose>0 0 0 0 -0 0</pose>
          <mass>0.1</mass>
          <inertia>
            <ixx>0.01</ixx>
            <ixy>0</ixy>
            <ixz>0</ixz>
            <iyy>0.01</iyy>
            <iyz>0</iyz>
            <izz>0.01</izz>
          </inertia>
        </inertial>
        <collision name='sphere_03_collision'>
          <pose>0 0 0 0 -0 0</pose>
          <geometry>
            <sphere>
              <radius>0.025</radius>
            </sphere>
          </geometry>
          <max_contacts>10</max_contacts>
          <surface>
            <contact>
              <ode/>
            </contact>
            <bounce/>
            <friction>
              <torsional>
                <ode/>
              </torsional>
              <ode/>
            </friction>
          </surface>
        </collision>
        <visual name='sphere_03_vis'>
          <pose>0 0 0 0 -0 0</pose>
          <geometry>
            <sphere>
              <radius>0.025</radius>
            </sphere>
          </geometry>
        </visual>
        <velocity_decay/>
        <self_collide>0</self_collide>
        <enable_wind>0</enable_wind>
        <kinematic>0</kinematic>
      </link>
      <joint name='joint_03_1' type='revolute'>
        <child>sphere_03</child>
        <parent>link_02</parent>
        <axis>
          <xyz expressed_in='__model__'>0 0 1</xyz>
          <limit>
            <lower>-0.7</lower>
            <upper>0.7</upper>
          </limit>
          <dynamics>
            <damping>10</damping>
            <friction>0</friction>
            <spring_reference>0</spring_reference>
            <spring_stiffness>0</spring_stiffness>
          </dynamics>
        </axis>
      </joint>
      <link name='link_03'>
        <gravity>0</gravity>
        <pose>0.5 0 0 0 -0 0</pose>
        <inertial>
          <pose>0 0 0 0 -0 0</pose>
          <mass>0.1</mass>
          <inertia>
            <ixx>0.01</ixx>
            <ixy>0</ixy>
            <ixz>0</ixz>
            <iyy>0.01</iyy>
            <iyz>0</iyz>
            <izz>0.01</izz>
          </inertia>
        </inertial>
        <collision name='link_03_collision'>
          <pose>0.1 0 0 0 1.57079 0</pose>
          <geometry>
            <cylinder>
              <length>0.2</length>
              <radius>0.025</radius>
            </cylinder>
          </geometry>
          <max_contacts>10</max_contacts>
          <surface>
            <contact>
              <ode/>
            </contact>
            <bounce/>
            <friction>
              <torsional>
                <ode/>
              </torsional>
              <ode/>
            </friction>
          </surface>
        </collision>
        <visual name='link_03_vis'>
          <pose>0.1 0 0 0 1.57079 0</pose>
          <geometry>
            <cylinder>
              <length>0.2</length>
              <radius>0.025</radius>
            </cylinder>
          </geometry>
        </visual>
        <velocity_decay/>
        <self_collide>0</self_collide>
        <enable_wind>0</enable_wind>
        <kinematic>0</kinematic>
      </link>
      <joint name='joint_03_2' type='revolute'>
        <child>link_03</child>
        <parent>sphere_03</parent>
        <axis>
          <xyz expressed_in='__model__'>0 1 0</xyz>
          <limit>
            <lower>-0.7</lower>
            <upper>0.7</upper>
          </limit>
          <dynamics>
            <damping>10</damping>
            <friction>0</friction>
            <spring_reference>0</spring_reference>
            <spring_stiffness>0</spring_stiffness>
          </dynamics>
        </axis>
      </joint>
      <link name='sphere_04'>
        <gravity>0</gravity>
        <pose>0.7 0 0 0 -0 0</pose>
        <inertial>
          <pose>0 0 0 0 -0 0</pose>
          <mass>0.1</mass>
          <inertia>
            <ixx>0.01</ixx>
            <ixy>0</ixy>
            <ixz>0</ixz>
            <iyy>0.01</iyy>
            <iyz>0</iyz>
            <izz>0.01</izz>
          </inertia>
        </inertial>
        <collision name='sphere_04_collision'>
          <pose>0 0 0 0 -0 0</pose>
          <geometry>
            <sphere>
              <radius>0.025</radius>
            </sphere>
          </geometry>
          <max_contacts>10</max_contacts>
          <surface>
            <contact>
              <ode/>
            </contact>
            <bounce/>
            <friction>
              <torsional>
                <ode/>
              </torsional>
              <ode/>
            </friction>
          </surface>
        </collision>
        <visual name='sphere_04_vis'>
          <pose>0 0 0 0 -0 0</pose>
          <geometry>
            <sphere>
              <radius>0.025</radius>
            </sphere>
          </geometry>
        </visual>
        <velocity_decay/>
        <self_collide>0</self_collide>
        <enable_wind>0</enable_wind>
        <kinematic>0</kinematic>
      </link>
      <joint name='joint_04_1' type='revolute'>
        <child>sphere_04</child>
        <parent>link_03</parent>
        <axis>
          <xyz expressed_in='__model__'>0 0 1</xyz>
          <limit>
            <lower>-0.7</lower>
            <upper>0.7</upper>
          </limit>
          <dynamics>
            <damping>10</damping>
            <friction>0</friction>
            <spring_reference>0</spring_reference>
            <spring_stiffness>0</spring_stiffness>
          </dynamics>
        </axis>
      </joint>
      <link name='link_04'>
        <gravity>0</gravity>
        <pose>0.7 0 0 0 -0 0</pose>
        <inertial>
          <pose>0 0 0 0 -0 0</pose>
          <mass>0.1</mass>
          <inertia>
            <ixx>0.01</ixx>
            <ixy>0</ixy>
            <ixz>0</ixz>
            <iyy>0.01</iyy>
            <iyz>0</iyz>
            <izz>0.01</izz>
          </inertia>
        </inertial>
        <collision name='link_04_collision'>
          <pose>0.1 0 0 0 1.57079 0</pose>
          <geometry>
            <cylinder>
              <length>0.2</length>
              <radius>0.025</radius>
            </cylinder>
          </geometry>
          <max_contacts>10</max_contacts>
          <surface>
            <contact>
              <ode/>
            </contact>
            <bounce/>
            <friction>
              <torsional>
                <ode/>
              </torsional>
              <ode/>
            </friction>
          </surface>
        </collision>
        <visual name='link_04_vis'>
          <pose>0.1 0 0 0 1.57079 0</pose>
          <geometry>
            <cylinder>
              <length>0.2</length>
              <radius>0.025</radius>
            </cylinder>
          </geometry>
        </visual>
        <velocity_decay/>
        <self_collide>0</self_collide>
        <enable_wind>0</enable_wind>
        <kinematic>0</kinematic>
      </link>
      <joint name='joint_04_2' type='revolute'>
        <child>link_04</child>
        <parent>sphere_04</parent>
        <axis>
          <xyz expressed_in='__model__'>0 1 0</xyz>
          <limit>
            <lower>-0.7</lower>
            <upper>0.7</upper>
          </limit>
          <dynamics>
            <damping>10</damping>
            <friction>0</friction>
            <spring_reference>0</spring_reference>
            <spring_stiffness>0</spring_stiffness>
          </dynamics>
        </axis>
      </joint>
      <link name='sphere_05'>
        <gravity>0</gravity>
        <pose>0.9 0 0 0 -0 0</pose>
        <inertial>
          <pose>0 0 0 0 -0 0</pose>
          <mass>0.1</mass>
          <inertia>
            <ixx>0.01</ixx>
            <ixy>0</ixy>
            <ixz>0</ixz>
            <iyy>0.01</iyy>
            <iyz>0</iyz>
            <izz>0.01</izz>
          </inertia>
        </inertial>
        <collision name='sphere_05_collision'>
          <pose>0 0 0 0 -0 0</pose>
          <geometry>
            <sphere>
              <radius>0.025</radius>
            </sphere>
          </geometry>
          <max_contacts>10</max_contacts>
          <surface>
            <contact>
              <ode/>
            </contact>
            <bounce/>
            <friction>
              <torsional>
                <ode/>
              </torsional>
              <ode/>
            </friction>
          </surface>
        </collision>
        <visual name='sphere_05_vis'>
          <pose>0 0 0 0 -0 0</pose>
          <geometry>
            <sphere>
              <radius>0.025</radius>
            </sphere>
          </geometry>
        </visual>
        <velocity_decay/>
        <self_collide>0</self_collide>
        <enable_wind>0</enable_wind>
        <kinematic>0</kinematic>
      </link>
      <joint name='joint_05_1' type='revolute'>
        <child>sphere_05</child>
        <parent>link_04</parent>
        <axis>
          <xyz expressed_in='__model__'>0 0 1</xyz>
          <limit>
            <lower>-0.7</lower>
            <upper>0.7</upper>
          </limit>
          <dynamics>
            <damping>10</damping>
            <friction>0</friction>
            <spring_reference>0</spring_reference>
            <spring_stiffness>0</spring_stiffness>
          </dynamics>
        </axis>
      </joint>
      <link name='link_05'>
        <gravity>0</gravity>
        <pose>0.9 0 0 0 -0 0</pose>
        <inertial>
          <pose>0 0 0 0 -0 0</pose>
          <mass>0.1</mass>
          <inertia>
            <ixx>0.01</ixx>
            <ixy>0</ixy>
            <ixz>0</ixz>
            <iyy>0.01</iyy>
            <iyz>0</iyz>
            <izz>0.01</izz>
          </inertia>
        </inertial>
        <collision name='link_05_collision'>
          <pose>0.1 0 0 0 1.57079 0</pose>
          <geometry>
            <cylinder>
              <length>0.2</length>
              <radius>0.025</radius>
            </cylinder>
          </geometry>
          <max_contacts>10</max_contacts>
          <surface>
            <contact>
              <ode/>
            </contact>
            <bounce/>
            <friction>
              <torsional>
                <ode/>
              </torsional>
              <ode/>
            </friction>
          </surface>
        </collision>
        <visual name='link_05_vis'>
          <pose>0.1 0 0 0 1.57079 0</pose>
          <geometry>
            <cylinder>
              <length>0.2</length>
              <radius>0.025</radius>
            </cylinder>
          </geometry>
        </visual>
        <velocity_decay/>
        <self_collide>0</self_collide>
        <enable_wind>0</enable_wind>
        <kinematic>0</kinematic>
      </link>
      <joint name='joint_05_2' type='revolute'>
        <child>link_05</child>
        <parent>sphere_05</parent>
        <axis>
          <xyz expressed_in='__model__'>0 1 0</xyz>
          <limit>
            <lower>-0.7</lower>
            <upper>0.7</upper>
          </limit>
          <dynamics>
            <damping>10</damping>
            <friction>0</friction>
            <spring_reference>0</spring_reference>
            <spring_stiffness>0</spring_stiffness>
          </dynamics>
        </axis>
      </joint>
      <link name='sphere_06'>
        <gravity>0</gravity>
        <pose>1.1 0 0 0 -0 0</pose>
        <inertial>
          <pose>0 0 0 0 -0 0</pose>
          <mass>0.1</mass>
          <inertia>
            <ixx>0.01</ixx>
            <ixy>0</ixy>
            <ixz>0</ixz>
            <iyy>0.01</iyy>
            <iyz>0</iyz>
            <izz>0.01</izz>
          </inertia>
        </inertial>
        <collision name='sphere_06_collision'>
          <pose>0 0 0 0 -0 0</pose>
          <geometry>
            <sphere>
              <radius>0.025</radius>
            </sphere>
          </geometry>
          <max_contacts>10</max_contacts>
          <surface>
            <contact>
              <ode/>
            </contact>
            <bounce/>
            <friction>
              <torsional>
                <ode/>
              </torsional>
              <ode/>
            </friction>
          </surface>
        </collision>
        <visual name='sphere_06_vis'>
          <pose>0 0 0 0 -0 0</pose>
          <geometry>
            <sphere>
              <radius>0.025</radius>
            </sphere>
          </geometry>
        </visual>
        <velocity_decay/>
        <self_collide>0</self_collide>
        <enable_wind>0</enable_wind>
        <kinematic>0</kinematic>
      </link>
      <joint name='joint_06_1' type='revolute'>
        <child>sphere_06</child>
        <parent>link_05</parent>
        <axis>
          <xyz expressed_in='__model__'>0 0 1</xyz>
          <limit>
            <lower>-0.7</lower>
            <upper>0.7</upper>
          </limit>
          <dynamics>
            <damping>10</damping>
            <friction>0</friction>
            <spring_reference>0</spring_reference>
            <spring_stiffness>0</spring_stiffness>
          </dynamics>
        </axis>
      </joint>
      <link name='link_06'>
        <gravity>0</gravity>
        <pose>1.1 0 0 0 -0 0</pose>
        <inertial>
          <pose>0 0 0 0 -0 0</pose>
          <mass>0.1</mass>
          <inertia>
            <ixx>0.01</ixx>
            <ixy>0</ixy>
            <ixz>0</ixz>
            <iyy>0.01</iyy>
            <iyz>0</iyz>
            <izz>0.01</izz>
          </inertia>
        </inertial>
        <collision name='link_06_collision'>
          <pose>0.1 0 0 0 1.57079 0</pose>
          <geometry>
            <cylinder>
              <length>0.2</length>
              <radius>0.025</radius>
            </cylinder>
          </geometry>
          <max_contacts>10</max_contacts>
          <surface>
            <contact>
              <ode/>
            </contact>
            <bounce/>
            <friction>
              <torsional>
                <ode/>
              </torsional>
              <ode/>
            </friction>
          </surface>
        </collision>
        <visual name='link_06_vis'>
          <pose>0.1 0 0 0 1.57079 0</pose>
          <geometry>
            <cylinder>
              <length>0.2</length>
              <radius>0.025</radius>
            </cylinder>
          </geometry>
        </visual>
        <velocity_decay/>
        <self_collide>0</self_collide>
        <enable_wind>0</enable_wind>
        <kinematic>0</kinematic>
      </link>
      <joint name='joint_06_2' type='revolute'>
        <child>link_06</child>
        <parent>sphere_06</parent>
        <axis>
          <xyz expressed_in='__model__'>0 1 0</xyz>
          <limit>
            <lower>-0.7</lower>
            <upper>0.7</upper>
          </limit>
          <dynamics>
            <damping>10</damping>
            <friction>0</friction>
            <spring_reference>0</spring_reference>
            <spring_stiffness>0</spring_stiffness>
          </dynamics>
        </axis>
      </joint>
      <link name='sphere_07'>
        <gravity>0</gravity>
        <pose>1.3 0 0 0 -0 0</pose>
        <inertial>
          <pose>0 0 0 0 -0 0</pose>
          <mass>0.1</mass>
          <inertia>
            <ixx>0.01</ixx>
            <ixy>0</ixy>
            <ixz>0</ixz>
            <iyy>0.01</iyy>
            <iyz>0</iyz>
            <izz>0.01</izz>
          </inertia>
        </inertial>
        <collision name='sphere_07_collision'>
          <pose>0 0 0 0 -0 0</pose>
          <geometry>
            <sphere>
              <radius>0.025</radius>
            </sphere>
          </geometry>
          <max_contacts>10</max_contacts>
          <surface>
            <contact>
              <ode/>
            </contact>
            <bounce/>
            <friction>
              <torsional>
                <ode/>
              </torsional>
              <ode/>
            </friction>
          </surface>
        </collision>
        <visual name='sphere_07_vis'>
          <pose>0 0 0 0 -0 0</pose>
          <geometry>
            <sphere>
              <radius>0.025</radius>
            </sphere>
          </geometry>
        </visual>
        <velocity_decay/>
        <self_collide>0</self_collide>
        <enable_wind>0</enable_wind>
        <kinematic>0</kinematic>
      </link>
      <joint name='joint_07_1' type='revolute'>
        <child>sphere_07</child>
        <parent>link_06</parent>
        <axis>
          <xyz expressed_in='__model__'>0 0 1</xyz>
          <limit>
            <lower>-0.7</lower>
            <upper>0.7</upper>
          </limit>
          <dynamics>
            <damping>10</damping>
            <friction>0</friction>
            <spring_reference>0</spring_reference>
            <spring_stiffness>0</spring_stiffness>
          </dynamics>
        </axis>
      </joint>
      <link name='link_07'>
        <gravity>0</gravity>
        <pose>1.3 0 0 0 -0 0</pose>
        <inertial>
          <pose>0 0 0 0 -0 0</pose>
          <mass>0.1</mass>
          <inertia>
            <ixx>0.01</ixx>
            <ixy>0</ixy>
            <ixz>0</ixz>
            <iyy>0.01</iyy>
            <iyz>0</iyz>
            <izz>0.01</izz>
          </inertia>
        </inertial>
        <collision name='link_07_collision'>
          <pose>0.1 0 0 0 1.57079 0</pose>
          <geometry>
            <cylinder>
              <length>0.2</length>
              <radius>0.025</radius>
            </cylinder>
          </geometry>
          <max_contacts>10</max_contacts>
          <surface>
            <contact>
              <ode/>
            </contact>
            <bounce/>
            <friction>
              <torsional>
                <ode/>
              </torsional>
              <ode/>
            </friction>
          </surface>
        </collision>
        <visual name='link_07_vis'>
          <pose>0.1 0 0 0 1.57079 0</pose>
          <geometry>
            <cylinder>
              <length>0.2</length>
              <radius>0.025</radius>
            </cylinder>
          </geometry>
        </visual>
        <velocity_decay/>
        <self_collide>0</self_collide>
        <enable_wind>0</enable_wind>
        <kinematic>0</kinematic>
      </link>
      <joint name='joint_07_2' type='revolute'>
        <child>link_07</child>
        <parent>sphere_07</parent>
        <axis>
          <xyz expressed_in='__model__'>0 1 0</xyz>
          <limit>
            <lower>-0.7</lower>
            <upper>0.7</upper>
          </limit>
          <dynamics>
            <damping>10</damping>
            <friction>0</friction>
            <spring_reference>0</spring_reference>
            <spring_stiffness>0</spring_stiffness>
          </dynamics>
        </axis>
      </joint>
      <link name='sphere_08'>
        <gravity>0</gravity>
        <pose>1.5 0 0 0 -0 0</pose>
        <inertial>
          <pose>0 0 0 0 -0 0</pose>
          <mass>0.1</mass>
          <inertia>
            <ixx>0.01</ixx>
            <ixy>0</ixy>
            <ixz>0</ixz>
            <iyy>0.01</iyy>
            <iyz>0</iyz>
            <izz>0.01</izz>
          </inertia>
        </inertial>
        <collision name='sphere_08_collision'>
          <pose>0 0 0 0 -0 0</pose>
          <geometry>
            <sphere>
              <radius>0.025</radius>
            </sphere>
          </geometry>
          <max_contacts>10</max_contacts>
          <surface>
            <contact>
              <ode/>
            </contact>
            <bounce/>
            <friction>
              <torsional>
                <ode/>
              </torsional>
              <ode/>
            </friction>
          </surface>
        </collision>
        <visual name='sphere_08_vis'>
          <pose>0 0 0 0 -0 0</pose>
          <geometry>
            <sphere>
              <radius>0.025</radius>
            </sphere>
          </geometry>
        </visual>
        <velocity_decay/>
        <self_collide>0</self_collide>
        <enable_wind>0</enable_wind>
        <kinematic>0</kinematic>
      </link>
      <joint name='joint_08_1' type='revolute'>
        <child>sphere_08</child>
        <parent>link_07</parent>
        <axis>
          <xyz expressed_in='__model__'>0 0 1</xyz>
          <limit>
            <lower>-0.7</lower>
            <upper>0.7</upper>
          </limit>
          <dynamics>
            <damping>10</damping>
            <friction>0</friction>
            <spring_reference>0</spring_reference>
            <spring_stiffness>0</spring_stiffness>
          </dynamics>
        </axis>
      </joint>
      <link name='link_08'>
        <gravity>0</gravity>
        <pose>1.5 0 0 0 -0 0</pose>
        <inertial>
          <pose>0 0 0 0 -0 0</pose>
          <mass>0.1</mass>
          <inertia>
            <ixx>0.01</ixx>
            <ixy>0</ixy>
            <ixz>0</ixz>
            <iyy>0.01</iyy>
            <iyz>0</iyz>
            <izz>0.01</izz>
          </inertia>
        </inertial>
        <collision name='link_08_collision'>
          <pose>0.1 0 0 0 1.57079 0</pose>
          <geometry>
            <cylinder>
              <length>0.2</length>
              <radius>0.025</radius>
            </cylinder>
          </geometry>
          <max_contacts>10</max_contacts>
          <surface>
            <contact>
              <ode/>
            </contact>
            <bounce/>
            <friction>
              <torsional>
                <ode/>
              </torsional>
              <ode/>
            </friction>
          </surface>
        </collision>
        <visual name='link_08_vis'>
          <pose>0.1 0 0 0 1.57079 0</pose>
          <geometry>
            <cylinder>
              <length>0.2</length>
              <radius>0.025</radius>
            </cylinder>
          </geometry>
        </visual>
        <velocity_decay/>
        <self_collide>0</self_collide>
        <enable_wind>0</enable_wind>
        <kinematic>0</kinematic>
      </link>
      <joint name='joint_08_2' type='revolute'>
        <child>link_08</child>
        <parent>sphere_08</parent>
        <axis>
          <xyz expressed_in='__model__'>0 1 0</xyz>
          <limit>
            <lower>-0.7</lower>
            <upper>0.7</upper>
          </limit>
          <dynamics>
            <damping>10</damping>
            <friction>0</friction>
            <spring_reference>0</spring_reference>
            <spring_stiffness>0</spring_stiffness>
          </dynamics>
        </axis>
      </joint>
      <link name='sphere_09'>
        <gravity>0</gravity>
        <pose>1.7 0 0 0 -0 0</pose>
        <inertial>
          <pose>0 0 0 0 -0 0</pose>
          <mass>0.1</mass>
          <inertia>
            <ixx>0.01</ixx>
            <ixy>0</ixy>
            <ixz>0</ixz>
            <iyy>0.01</iyy>
            <iyz>0</iyz>
            <izz>0.01</izz>
          </inertia>
        </inertial>
        <collision name='sphere_09_collision'>
          <pose>0 0 0 0 -0 0</pose>
          <geometry>
            <sphere>
              <radius>0.025</radius>
            </sphere>
          </geometry>
          <max_contacts>10</max_contacts>
          <surface>
            <contact>
              <ode/>
            </contact>
            <bounce/>
            <friction>
              <torsional>
                <ode/>
              </torsional>
              <ode/>
            </friction>
          </surface>
        </collision>
        <visual name='sphere_09_vis'>
          <pose>0 0 0 0 -0 0</pose>
          <geometry>
            <sphere>
              <radius>0.025</radius>
            </sphere>
          </geometry>
        </visual>
        <velocity_decay/>
        <self_collide>0</self_collide>
        <enable_wind>0</enable_wind>
        <kinematic>0</kinematic>
      </link>
      <joint name='joint_09_1' type='revolute'>
        <child>sphere_09</child>
        <parent>link_08</parent>
        <axis>
          <xyz expressed_in='__model__'>0 0 1</xyz>
          <limit>
            <lower>-0.7</lower>
            <upper>0.7</upper>
          </limit>
          <dynamics>
            <damping>10</damping>
            <friction>0</friction>
            <spring_reference>0</spring_reference>
            <spring_stiffness>0</spring_stiffness>
          </dynamics>
        </axis>
      </joint>
      <link name='link_09'>
        <gravity>0</gravity>
        <pose>1.7 0 0 0 -0 0</pose>
        <inertial>
          <pose>0 0 0 0 -0 0</pose>
          <mass>0.1</mass>
          <inertia>
            <ixx>0.01</ixx>
            <ixy>0</ixy>
            <ixz>0</ixz>
            <iyy>0.01</iyy>
            <iyz>0</iyz>
            <izz>0.01</izz>
          </inertia>
        </inertial>
        <collision name='link_09_collision'>
          <pose>0.1 0 0 0 1.57079 0</pose>
          <geometry>
            <cylinder>
              <length>0.2</length>
              <radius>0.025</radius>
            </cylinder>
          </geometry>
          <max_contacts>10</max_contacts>
          <surface>
            <contact>
              <ode/>
            </contact>
            <bounce/>
            <friction>
              <torsional>
                <ode/>
              </torsional>
              <ode/>
            </friction>
          </surface>
        </collision>
        <visual name='link_09_vis'>
          <pose>0.1 0 0 0 1.57079 0</pose>
          <geometry>
            <cylinder>
              <length>0.2</length>
              <radius>0.025</radius>
            </cylinder>
          </geometry>
        </visual>
        <velocity_decay/>
        <self_collide>0</self_collide>
        <enable_wind>0</enable_wind>
        <kinematic>0</kinematic>
      </link>
      <joint name='joint_09_2' type='revolute'>
        <child>link_09</child>
        <parent>sphere_09</parent>
        <axis>
          <xyz expressed_in='__model__'>0 1 0</xyz>
          <limit>
            <lower>-0.7</lower>
            <upper>0.7</upper>
          </limit>
          <dynamics>
            <damping>10</damping>
            <friction>0</friction>
            <spring_reference>0</spring_reference>
            <spring_stiffness>0</spring_stiffness>
          </dynamics>
        </axis>
      </joint>
      <link name='sphere_10'>
        <gravity>0</gravity>
        <pose>1.9 0 0 0 -0 0</pose>
        <inertial>
          <pose>0 0 0 0 -0 0</pose>
          <mass>0.1</mass>
          <inertia>
            <ixx>0.01</ixx>
            <ixy>0</ixy>
            <ixz>0</ixz>
            <iyy>0.01</iyy>
            <iyz>0</iyz>
            <izz>0.01</izz>
          </inertia>
        </inertial>
        <collision name='sphere_10_collision'>
          <pose>0 0 0 0 -0 0</pose>
          <geometry>
            <sphere>
              <radius>0.025</radius>
            </sphere>
          </geometry>
          <max_contacts>10</max_contacts>
          <surface>
            <contact>
              <ode/>
            </contact>
            <bounce/>
            <friction>
              <torsional>
                <ode/>
              </torsional>
              <ode/>
            </friction>
          </surface>
        </collision>
        <visual name='sphere_10_vis'>
          <pose>0 0 0 0 -0 0</pose>
          <geometry>
            <sphere>
              <radius>0.025</radius>
            </sphere>
          </geometry>
        </visual>
        <velocity_decay/>
        <self_collide>0</self_collide>
        <enable_wind>0</enable_wind>
        <kinematic>0</kinematic>
      </link>
      <joint name='joint_10_1' type='revolute'>
        <child>sphere_10</child>
        <parent>link_09</parent>
        <axis>
          <xyz expressed_in='__model__'>0 0 1</xyz>
          <limit>
            <lower>-0.7</lower>
            <upper>0.7</upper>
          </limit>
          <dynamics>
            <damping>10</damping>
            <friction>0</friction>
            <spring_reference>0</spring_reference>
            <spring_stiffness>0</spring_stiffness>
          </dynamics>
        </axis>
      </joint>
      <link name='link_10'>
        <gravity>0</gravity>
        <pose>1.9 0 0 0 -0 0</pose>
        <inertial>
          <pose>0 0 0 0 -0 0</pose>
          <mass>0.1</mass>
          <inertia>
            <ixx>0.01</ixx>
            <ixy>0</ixy>
            <ixz>0</ixz>
            <iyy>0.01</iyy>
            <iyz>0</iyz>
            <izz>0.01</izz>
          </inertia>
        </inertial>
        <collision name='link_10_collision'>
          <pose>0.1 0 0 0 1.57079 0</pose>
          <geometry>
            <cylinder>
              <length>0.2</length>
              <radius>0.025</radius>
            </cylinder>
          </geometry>
          <max_contacts>10</max_contacts>
          <surface>
            <contact>
              <ode/>
            </contact>
            <bounce/>
            <friction>
              <torsional>
                <ode/>
              </torsional>
              <ode/>
            </friction>
          </surface>
        </collision>
        <visual name='link_10_vis'>
          <pose>0.1 0 0 0 1.57079 0</pose>
          <geometry>
            <cylinder>
              <length>0.2</length>
              <radius>0.025</radius>
            </cylinder>
          </geometry>
        </visual>
        <velocity_decay/>
        <self_collide>0</self_collide>
        <enable_wind>0</enable_wind>
        <kinematic>0</kinematic>
      </link>
      <joint name='joint_10_2' type='revolute'>
        <child>link_10</child>
        <parent>sphere_10</parent>
        <axis>
          <xyz expressed_in='__model__'>0 1 0</xyz>
          <limit>
            <lower>-0.7</lower>
            <upper>0.7</upper>
          </limit>
          <dynamics>
            <damping>10</damping>
            <friction>0</friction>
            <spring_reference>0</spring_reference>
            <spring_stiffness>0</spring_stiffness>
          </dynamics>
        </axis>
      </joint>
      <link name='sphere_11'>
        <gravity>0</gravity>
        <pose>2.1 0 0 0 -0 0</pose>
        <inertial>
          <pose>0 0 0 0 -0 0</pose>
          <mass>0.1</mass>
          <inertia>
            <ixx>0.01</ixx>
            <ixy>0</ixy>
            <ixz>0</ixz>
            <iyy>0.01</iyy>
            <iyz>0</iyz>
            <izz>0.01</izz>
          </inertia>
        </inertial>
        <collision name='sphere_11_collision'>
          <pose>0 0 0 0 -0 0</pose>
          <geometry>
            <sphere>
              <radius>0.025</radius>
            </sphere>
          </geometry>
          <max_contacts>10</max_contacts>
          <surface>
            <contact>
              <ode/>
            </contact>
            <bounce/>
            <friction>
              <torsional>
                <ode/>
              </torsional>
              <ode/>
            </friction>
          </surface>
        </collision>
        <visual name='sphere_11_vis'>
          <pose>0 0 0 0 -0 0</pose>
          <geometry>
            <sphere>
              <radius>0.025</radius>
            </sphere>
          </geometry>
        </visual>
        <velocity_decay/>
        <self_collide>0</self_collide>
        <enable_wind>0</enable_wind>
        <kinematic>0</kinematic>
      </link>
      <joint name='joint_11_1' type='revolute'>
        <child>sphere_11</child>
        <parent>link_10</parent>
        <axis>
          <xyz expressed_in='__model__'>0 0 1</xyz>
          <limit>
            <lower>-0.7</lower>
            <upper>0.7</upper>
          </limit>
          <dynamics>
            <damping>10</damping>
            <friction>0</friction>
            <spring_reference>0</spring_reference>
            <spring_stiffness>0</spring_stiffness>
          </dynamics>
        </axis>
      </joint>
      <link name='link_11'>
        <gravity>0</gravity>
        <pose>2.1 0 0 0 -0 0</pose>
        <inertial>
          <pose>0 0 0 0 -0 0</pose>
          <mass>0.1</mass>
          <inertia>
            <ixx>0.01</ixx>
            <ixy>0</ixy>
            <ixz>0</ixz>
            <iyy>0.01</iyy>
            <iyz>0</iyz>
            <izz>0.01</izz>
          </inertia>
        </inertial>
        <collision name='link_11_collision'>
          <pose>0.1 0 0 0 1.57079 0</pose>
          <geometry>
            <cylinder>
              <length>0.2</length>
              <radius>0.025</radius>
            </cylinder>
          </geometry>
          <max_contacts>10</max_contacts>
          <surface>
            <contact>
              <ode/>
            </contact>
            <bounce/>
            <friction>
              <torsional>
                <ode/>
              </torsional>
              <ode/>
            </friction>
          </surface>
        </collision>
        <visual name='link_11_vis'>
          <pose>0.1 0 0 0 1.57079 0</pose>
          <geometry>
            <cylinder>
              <length>0.2</length>
              <radius>0.025</radius>
            </cylinder>
          </geometry>
        </visual>
        <velocity_decay/>
        <self_collide>0</self_collide>
        <enable_wind>0</enable_wind>
        <kinematic>0</kinematic>
      </link>
      <joint name='joint_11_2' type='revolute'>
        <child>link_11</child>
        <parent>sphere_11</parent>
        <axis>
          <xyz expressed_in='__model__'>0 1 0</xyz>
          <limit>
            <lower>-0.7</lower>
            <upper>0.7</upper>
          </limit>
          <dynamics>
            <damping>10</damping>
            <friction>0</friction>
            <spring_reference>0</spring_reference>
            <spring_stiffness>0</spring_stiffness>
          </dynamics>
        </axis>
      </joint>
      <link name='sphere_12'>
        <gravity>0</gravity>
        <pose>2.3 0 0 0 -0 0</pose>
        <inertial>
          <pose>0 0 0 0 -0 0</pose>
          <mass>0.1</mass>
          <inertia>
            <ixx>0.01</ixx>
            <ixy>0</ixy>
            <ixz>0</ixz>
            <iyy>0.01</iyy>
            <iyz>0</iyz>
            <izz>0.01</izz>
          </inertia>
        </inertial>
        <collision name='sphere_12_collision'>
          <pose>0 0 0 0 -0 0</pose>
          <geometry>
            <sphere>
              <radius>0.025</radius>
            </sphere>
          </geometry>
          <max_contacts>10</max_contacts>
          <surface>
            <contact>
              <ode/>
            </contact>
            <bounce/>
            <friction>
              <torsional>
                <ode/>
              </torsional>
              <ode/>
            </friction>
          </surface>
        </collision>
        <visual name='sphere_12_vis'>
          <pose>0 0 0 0 -0 0</pose>
          <geometry>
            <sphere>
              <radius>0.025</radius>
            </sphere>
          </geometry>
        </visual>
        <velocity_decay/>
        <self_collide>0</self_collide>
        <enable_wind>0</enable_wind>
        <kinematic>0</kinematic>
      </link>
      <joint name='joint_12_1' type='revolute'>
        <child>sphere_12</child>
        <parent>link_11</parent>
        <axis>
          <xyz expressed_in='__model__'>0 0 1</xyz>
          <limit>
            <lower>-0.7</lower>
            <upper>0.7</upper>
          </limit>
          <dynamics>
            <damping>10</damping>
            <friction>0</friction>
            <spring_reference>0</spring_reference>
            <spring_stiffness>0</spring_stiffness>
          </dynamics>
        </axis>
      </joint>
      <link name='link_12'>
        <gravity>0</gravity>
        <pose>2.3 0 0 0 -0 0</pose>
        <inertial>
          <pose>0 0 0 0 -0 0</pose>
          <mass>0.1</mass>
          <inertia>
            <ixx>0.01</ixx>
            <ixy>0</ixy>
            <ixz>0</ixz>
            <iyy>0.01</iyy>
            <iyz>0</iyz>
            <izz>0.01</izz>
          </inertia>
        </inertial>
        <collision name='link_12_collision'>
          <pose>0.1 0 0 0 1.57079 0</pose>
          <geometry>
            <cylinder>
              <length>0.2</length>
              <radius>0.025</radius>
            </cylinder>
          </geometry>
          <max_contacts>10</max_contacts>
          <surface>
            <contact>
              <ode/>
            </contact>
            <bounce/>
            <friction>
              <torsional>
                <ode/>
              </torsional>
              <ode/>
            </friction>
          </surface>
        </collision>
        <visual name='link_12_vis'>
          <pose>0.1 0 0 0 1.57079 0</pose>
          <geometry>
            <cylinder>
              <length>0.2</length>
              <radius>0.025</radius>
            </cylinder>
          </geometry>
        </visual>
        <velocity_decay/>
        <self_collide>0</self_collide>
        <enable_wind>0</enable_wind>
        <kinematic>0</kinematic>
      </link>
      <joint name='joint_12_2' type='revolute'>
        <child>link_12</child>
        <parent>sphere_12</parent>
        <axis>
          <xyz expressed_in='__model__'>0 1 0</xyz>
          <limit>
            <lower>-0.7</lower>
            <upper>0.7</upper>
          </limit>
          <dynamics>
            <damping>10</damping>
            <friction>0</friction>
            <spring_reference>0</spring_reference>
            <spring_stiffness>0</spring_stiffness>
          </dynamics>
        </axis>
      </joint>
      <link name='sphere_13'>
        <gravity>0</gravity>
        <pose>2.5 0 0 0 -0 0</pose>
        <inertial>
          <pose>0 0 0 0 -0 0</pose>
          <mass>0.1</mass>
          <inertia>
            <ixx>0.01</ixx>
            <ixy>0</ixy>
            <ixz>0</ixz>
            <iyy>0.01</iyy>
            <iyz>0</iyz>
            <izz>0.01</izz>
          </inertia>
        </inertial>
        <collision name='sphere_13_collision'>
          <pose>0 0 0 0 -0 0</pose>
          <geometry>
            <sphere>
              <radius>0.025</radius>
            </sphere>
          </geometry>
          <max_contacts>10</max_contacts>
          <surface>
            <contact>
              <ode/>
            </contact>
            <bounce/>
            <friction>
              <torsional>
                <ode/>
              </torsional>
              <ode/>
            </friction>
          </surface>
        </collision>
        <visual name='sphere_13_vis'>
          <pose>0 0 0 0 -0 0</pose>
          <geometry>
            <sphere>
              <radius>0.025</radius>
            </sphere>
          </geometry>
        </visual>
        <velocity_decay/>
        <self_collide>0</self_collide>
        <enable_wind>0</enable_wind>
        <kinematic>0</kinematic>
      </link>
      <joint name='joint_13_1' type='revolute'>
        <child>sphere_13</child>
        <parent>link_12</parent>
        <axis>
          <xyz expressed_in='__model__'>0 0 1</xyz>
          <limit>
            <lower>-0.7</lower>
            <upper>0.7</upper>
          </limit>
          <dynamics>
            <damping>10</damping>
            <friction>0</friction>
            <spring_reference>0</spring_reference>
            <spring_stiffness>0</spring_stiffness>
          </dynamics>
        </axis>
      </joint>
      <link name='link_13'>
        <gravity>0</gravity>
        <pose>2.5 0 0 0 -0 0</pose>
        <inertial>
          <pose>0 0 0 0 -0 0</pose>
          <mass>0.1</mass>
          <inertia>
            <ixx>0.01</ixx>
            <ixy>0</ixy>
            <ixz>0</ixz>
            <iyy>0.01</iyy>
            <iyz>0</iyz>
            <izz>0.01</izz>
          </inertia>
        </inertial>
        <collision name='link_13_collision'>
          <pose>0.1 0 0 0 1.57079 0</pose>
          <geometry>
            <cylinder>
              <length>0.2</length>
              <radius>0.025</radius>
            </cylinder>
          </geometry>
          <max_contacts>10</max_contacts>
          <surface>
            <contact>
              <ode/>
            </contact>
            <bounce/>
            <friction>
              <torsional>
                <ode/>
              </torsional>
              <ode/>
            </friction>
          </surface>
        </collision>
        <visual name='link_13_vis'>
          <pose>0.1 0 0 0 1.57079 0</pose>
          <geometry>
            <cylinder>
              <length>0.2</length>
              <radius>0.025</radius>
            </cylinder>
          </geometry>
        </visual>
        <velocity_decay/>
        <self_collide>0</self_collide>
        <enable_wind>0</enable_wind>
        <kinematic>0</kinematic>
      </link>
      <joint name='joint_13_2' type='revolute'>
        <child>link_13</child>
        <parent>sphere_13</parent>
        <axis>
          <xyz expressed_in='__model__'>0 1 0</xyz>
          <limit>
            <lower>-0.7</lower>
            <upper>0.7</upper>
          </limit>
          <dynamics>
            <damping>10</damping>
            <friction>0</friction>
            <spring_reference>0</spring_reference>
            <spring_stiffness>0</spring_stiffness>
          </dynamics>
        </axis>
      </joint>
      <link name='sphere_14'>
        <gravity>0</gravity>
        <pose>2.7 0 0 0 -0 0</pose>
        <inertial>
          <pose>0 0 0 0 -0 0</pose>
          <mass>0.1</mass>
          <inertia>
            <ixx>0.01</ixx>
            <ixy>0</ixy>
            <ixz>0</ixz>
            <iyy>0.01</iyy>
            <iyz>0</iyz>
            <izz>0.01</izz>
          </inertia>
        </inertial>
        <collision name='sphere_14_collision'>
          <pose>0 0 0 0 -0 0</pose>
          <geometry>
            <sphere>
              <radius>0.025</radius>
            </sphere>
          </geometry>
          <max_contacts>10</max_contacts>
          <surface>
            <contact>
              <ode/>
            </contact>
            <bounce/>
            <friction>
              <torsional>
                <ode/>
              </torsional>
              <ode/>
            </friction>
          </surface>
        </collision>
        <visual name='sphere_14_vis'>
          <pose>0 0 0 0 -0 0</pose>
          <geometry>
            <sphere>
              <radius>0.025</radius>
            </sphere>
          </geometry>
        </visual>
        <velocity_decay/>
        <self_collide>0</self_collide>
        <enable_wind>0</enable_wind>
        <kinematic>0</kinematic>
      </link>
      <joint name='joint_14_1' type='revolute'>
        <child>sphere_14</child>
        <parent>link_13</parent>
        <axis>
          <xyz expressed_in='__model__'>0 0 1</xyz>
          <limit>
            <lower>-0.7</lower>
            <upper>0.7</upper>
          </limit>
          <dynamics>
            <damping>10</damping>
            <friction>0</friction>
            <spring_reference>0</spring_reference>
            <spring_stiffness>0</spring_stiffness>
          </dynamics>
        </axis>
      </joint>
      <link name='link_14'>
        <gravity>0</gravity>
        <pose>2.7 0 0 0 -0 0</pose>
        <inertial>
          <pose>0 0 0 0 -0 0</pose>
          <mass>0.1</mass>
          <inertia>
            <ixx>0.01</ixx>
            <ixy>0</ixy>
            <ixz>0</ixz>
            <iyy>0.01</iyy>
            <iyz>0</iyz>
            <izz>0.01</izz>
          </inertia>
        </inertial>
        <collision name='link_14_collision'>
          <pose>0.1 0 0 0 1.57079 0</pose>
          <geometry>
            <cylinder>
              <length>0.2</length>
              <radius>0.025</radius>
            </cylinder>
          </geometry>
          <max_contacts>10</max_contacts>
          <surface>
            <contact>
              <ode/>
            </contact>
            <bounce/>
            <friction>
              <torsional>
                <ode/>
              </torsional>
              <ode/>
            </friction>
          </surface>
        </collision>
        <visual name='link_14_vis'>
          <pose>0.1 0 0 0 1.57079 0</pose>
          <geometry>
            <cylinder>
              <length>0.2</length>
              <radius>0.025</radius>
            </cylinder>
          </geometry>
        </visual>
        <velocity_decay/>
        <self_collide>0</self_collide>
        <enable_wind>0</enable_wind>
        <kinematic>0</kinematic>
      </link>
      <joint name='joint_14_2' type='revolute'>
        <child>link_14</child>
        <parent>sphere_14</parent>
        <axis>
          <xyz expressed_in='__model__'>0 1 0</xyz>
          <limit>
            <lower>-0.7</lower>
            <upper>0.7</upper>
          </limit>
          <dynamics>
            <damping>10</damping>
            <friction>0</friction>
            <spring_reference>0</spring_reference>
            <spring_stiffness>0</spring_stiffness>
          </dynamics>
        </axis>
      </joint>
      <link name='sphere_15'>
        <gravity>0</gravity>
        <pose>2.9 0 0 0 -0 0</pose>
        <inertial>
          <pose>0 0 0 0 -0 0</pose>
          <mass>0.1</mass>
          <inertia>
            <ixx>0.01</ixx>
            <ixy>0</ixy>
            <ixz>0</ixz>
            <iyy>0.01</iyy>
            <iyz>0</iyz>
            <izz>0.01</izz>
          </inertia>
        </inertial>
        <collision name='sphere_15_collision'>
          <pose>0 0 0 0 -0 0</pose>
          <geometry>
            <sphere>
              <radius>0.025</radius>
            </sphere>
          </geometry>
          <max_contacts>10</max_contacts>
          <surface>
            <contact>
              <ode/>
            </contact>
            <bounce/>
            <friction>
              <torsional>
                <ode/>
              </torsional>
              <ode/>
            </friction>
          </surface>
        </collision>
        <visual name='sphere_15_vis'>
          <pose>0 0 0 0 -0 0</pose>
          <geometry>
            <sphere>
              <radius>0.025</radius>
            </sphere>
          </geometry>
        </visual>
        <velocity_decay/>
        <self_collide>0</self_collide>
        <enable_wind>0</enable_wind>
        <kinematic>0</kinematic>
      </link>
      <joint name='joint_15_1' type='revolute'>
        <child>sphere_15</child>
        <parent>link_14</parent>
        <axis>
          <xyz expressed_in='__model__'>0 0 1</xyz>
          <limit>
            <lower>-0.7</lower>
            <upper>0.7</upper>
          </limit>
          <dynamics>
            <damping>10</damping>
            <friction>0</friction>
            <spring_reference>0</spring_reference>
            <spring_stiffness>0</spring_stiffness>
          </dynamics>
        </axis>
      </joint>
      <link name='link_15'>
        <gravity>0</gravity>
        <pose>2.9 0 0 0 -0 0</pose>
        <inertial>
          <pose>0 0 0 0 -0 0</pose>
          <mass>0.1</mass>
          <inertia>
            <ixx>0.01</ixx>
            <ixy>0</ixy>
            <ixz>0</ixz>
            <iyy>0.01</iyy>
            <iyz>0</iyz>
            <izz>0.01</izz>
          </inertia>
        </inertial>
        <collision name='link_15_collision'>
          <pose>0.1 0 0 0 1.57079 0</pose>
          <geometry>
            <cylinder>
              <length>0.2</length>
              <radius>0.025</radius>
            </cylinder>
          </geometry>
          <max_contacts>10</max_contacts>
          <surface>
            <contact>
              <ode/>
            </contact>
            <bounce/>
            <friction>
              <torsional>
                <ode/>
              </torsional>
              <ode/>
            </friction>
          </surface>
        </collision>
        <visual name='link_15_vis'>
          <pose>0.1 0 0 0 1.57079 0</pose>
          <geometry>
            <cylinder>
              <length>0.2</length>
              <radius>0.025</radius>
            </cylinder>
          </geometry>
        </visual>
        <velocity_decay/>
        <self_collide>0</self_collide>
        <enable_wind>0</enable_wind>
        <kinematic>0</kinematic>
      </link>
      <joint name='joint_15_2' type='revolute'>
        <child>link_15</child>
        <parent>sphere_15</parent>
        <axis>
          <xyz expressed_in='__model__'>0 1 0</xyz>
          <limit>
            <lower>-0.7</lower>
            <upper>0.7</upper>
          </limit>
          <dynamics>
            <damping>10</damping>
            <friction>0</friction>
            <spring_reference>0</spring_reference>
            <spring_stiffness>0</spring_stiffness>
          </dynamics>
        </axis>
      </joint>
      <link name='sphere_16'>
        <gravity>0</gravity>
        <pose>3.1 0 0 0 -0 0</pose>
        <inertial>
          <pose>0 0 0 0 -0 0</pose>
          <mass>0.1</mass>
          <inertia>
            <ixx>0.01</ixx>
            <ixy>0</ixy>
            <ixz>0</ixz>
            <iyy>0.01</iyy>
            <iyz>0</iyz>
            <izz>0.01</izz>
          </inertia>
        </inertial>
        <collision name='sphere_16_collision'>
          <pose>0 0 0 0 -0 0</pose>
          <geometry>
            <sphere>
              <radius>0.025</radius>
            </sphere>
          </geometry>
          <max_contacts>10</max_contacts>
          <surface>
            <contact>
              <ode/>
            </contact>
            <bounce/>
            <friction>
              <torsional>
                <ode/>
              </torsional>
              <ode/>
            </friction>
          </surface>
        </collision>
        <visual name='sphere_16_vis'>
          <pose>0 0 0 0 -0 0</pose>
          <geometry>
            <sphere>
              <radius>0.025</radius>
            </sphere>
          </geometry>
        </visual>
        <velocity_decay/>
        <self_collide>0</self_collide>
        <enable_wind>0</enable_wind>
        <kinematic>0</kinematic>
      </link>
      <joint name='joint_16_1' type='revolute'>
        <child>sphere_16</child>
        <parent>link_15</parent>
        <axis>
          <xyz expressed_in='__model__'>0 0 1</xyz>
          <limit>
            <lower>-0.7</lower>
            <upper>0.7</upper>
          </limit>
          <dynamics>
            <damping>10</damping>
            <friction>0</friction>
            <spring_reference>0</spring_reference>
            <spring_stiffness>0</spring_stiffness>
          </dynamics>
        </axis>
      </joint>
      <link name='link_16'>
        <gravity>0</gravity>
        <pose>3.1 0 0 0 -0 0</pose>
        <inertial>
          <pose>0 0 0 0 -0 0</pose>
          <mass>0.1</mass>
          <inertia>
            <ixx>0.01</ixx>
            <ixy>0</ixy>
            <ixz>0</ixz>
            <iyy>0.01</iyy>
            <iyz>0</iyz>
            <izz>0.01</izz>
          </inertia>
        </inertial>
        <collision name='link_16_collision'>
          <pose>0.1 0 0 0 1.57079 0</pose>
          <geometry>
            <cylinder>
              <length>0.2</length>
              <radius>0.025</radius>
            </cylinder>
          </geometry>
          <max_contacts>10</max_contacts>
          <surface>
            <contact>
              <ode/>
            </contact>
            <bounce/>
            <friction>
              <torsional>
                <ode/>
              </torsional>
              <ode/>
            </friction>
          </surface>
        </collision>
        <visual name='link_16_vis'>
          <pose>0.1 0 0 0 1.57079 0</pose>
          <geometry>
            <cylinder>
              <length>0.2</length>
              <radius>0.025</radius>
            </cylinder>
          </geometry>
        </visual>
        <velocity_decay/>
        <self_collide>0</self_collide>
        <enable_wind>0</enable_wind>
        <kinematic>0</kinematic>
      </link>
      <joint name='joint_16_2' type='revolute'>
        <child>link_16</child>
        <parent>sphere_16</parent>
        <axis>
          <xyz expressed_in='__model__'>0 1 0</xyz>
          <limit>
            <lower>-0.7</lower>
            <upper>0.7</upper>
          </limit>
          <dynamics>
            <damping>10</damping>
            <friction>0</friction>
            <spring_reference>0</spring_reference>
            <spring_stiffness>0</spring_stiffness>
          </dynamics>
        </axis>
      </joint>
      <link name='sphere_17'>
        <gravity>0</gravity>
        <pose>3.3 0 0 0 -0 0</pose>
        <inertial>
          <pose>0 0 0 0 -0 0</pose>
          <mass>0.1</mass>
          <inertia>
            <ixx>0.01</ixx>
            <ixy>0</ixy>
            <ixz>0</ixz>
            <iyy>0.01</iyy>
            <iyz>0</iyz>
            <izz>0.01</izz>
          </inertia>
        </inertial>
        <collision name='sphere_17_collision'>
          <pose>0 0 0 0 -0 0</pose>
          <geometry>
            <sphere>
              <radius>0.025</radius>
            </sphere>
          </geometry>
          <max_contacts>10</max_contacts>
          <surface>
            <contact>
              <ode/>
            </contact>
            <bounce/>
            <friction>
              <torsional>
                <ode/>
              </torsional>
              <ode/>
            </friction>
          </surface>
        </collision>
        <visual name='sphere_17_vis'>
          <pose>0 0 0 0 -0 0</pose>
          <geometry>
            <sphere>
              <radius>0.025</radius>
            </sphere>
          </geometry>
        </visual>
        <velocity_decay/>
        <self_collide>0</self_collide>
        <enable_wind>0</enable_wind>
        <kinematic>0</kinematic>
      </link>
      <joint name='joint_17_1' type='revolute'>
        <child>sphere_17</child>
        <parent>link_16</parent>
        <axis>
          <xyz expressed_in='__model__'>0 0 1</xyz>
          <limit>
            <lower>-0.7</lower>
            <upper>0.7</upper>
          </limit>
          <dynamics>
            <damping>10</damping>
            <friction>0</friction>
            <spring_reference>0</spring_reference>
            <spring_stiffness>0</spring_stiffness>
          </dynamics>
        </axis>
      </joint>
      <link name='link_17'>
        <gravity>0</gravity>
        <pose>3.3 0 0 0 -0 0</pose>
        <inertial>
          <pose>0 0 0 0 -0 0</pose>
          <mass>0.1</mass>
          <inertia>
            <ixx>0.01</ixx>
            <ixy>0</ixy>
            <ixz>0</ixz>
            <iyy>0.01</iyy>
            <iyz>0</iyz>
            <izz>0.01</izz>
          </inertia>
        </inertial>
        <collision name='link_17_collision'>
          <pose>0.1 0 0 0 1.57079 0</pose>
          <geometry>
            <cylinder>
              <length>0.2</length>
              <radius>0.025</radius>
            </cylinder>
          </geometry>
          <max_contacts>10</max_contacts>
          <surface>
            <contact>
              <ode/>
            </contact>
            <bounce/>
            <friction>
              <torsional>
                <ode/>
              </torsional>
              <ode/>
            </friction>
          </surface>
        </collision>
        <visual name='link_17_vis'>
          <pose>0.1 0 0 0 1.57079 0</pose>
          <geometry>
            <cylinder>
              <length>0.2</length>
              <radius>0.025</radius>
            </cylinder>
          </geometry>
        </visual>
        <velocity_decay/>
        <self_collide>0</self_collide>
        <enable_wind>0</enable_wind>
        <kinematic>0</kinematic>
      </link>
      <joint name='joint_17_2' type='revolute'>
        <child>link_17</child>
        <parent>sphere_17</parent>
        <axis>
          <xyz expressed_in='__model__'>0 1 0</xyz>
          <limit>
            <lower>-0.7</lower>
            <upper>0.7</upper>
          </limit>
          <dynamics>
            <damping>10</damping>
            <friction>0</friction>
            <spring_reference>0</spring_reference>
            <spring_stiffness>0</spring_stiffness>
          </dynamics>
        </axis>
      </joint>
      <link name='sphere_18'>
        <gravity>0</gravity>
        <pose>3.5 0 0 0 -0 0</pose>
        <inertial>
          <pose>0 0 0 0 -0 0</pose>
          <mass>0.1</mass>
          <inertia>
            <ixx>0.01</ixx>
            <ixy>0</ixy>
            <ixz>0</ixz>
            <iyy>0.01</iyy>
            <iyz>0</iyz>
            <izz>0.01</izz>
          </inertia>
        </inertial>
        <collision name='sphere_18_collision'>
          <pose>0 0 0 0 -0 0</pose>
          <geometry>
            <sphere>
              <radius>0.025</radius>
            </sphere>
          </geometry>
          <max_contacts>10</max_contacts>
          <surface>
            <contact>
              <ode/>
            </contact>
            <bounce/>
            <friction>
              <torsional>
                <ode/>
              </torsional>
              <ode/>
            </friction>
          </surface>
        </collision>
        <visual name='sphere_18_vis'>
          <pose>0 0 0 0 -0 0</pose>
          <geometry>
            <sphere>
              <radius>0.025</radius>
            </sphere>
          </geometry>
        </visual>
        <velocity_decay/>
        <self_collide>0</self_collide>
        <enable_wind>0</enable_wind>
        <kinematic>0</kinematic>
      </link>
      <joint name='joint_18_1' type='revolute'>
        <child>sphere_18</child>
        <parent>link_17</parent>
        <axis>
          <xyz expressed_in='__model__'>0 0 1</xyz>
          <limit>
            <lower>-0.7</lower>
            <upper>0.7</upper>
          </limit>
          <dynamics>
            <damping>10</damping>
            <friction>0</friction>
            <spring_reference>0</spring_reference>
            <spring_stiffness>0</spring_stiffness>
          </dynamics>
        </axis>
      </joint>
      <link name='link_18'>
        <gravity>0</gravity>
        <pose>3.5 0 0 0 -0 0</pose>
        <inertial>
          <pose>0 0 0 0 -0 0</pose>
          <mass>0.1</mass>
          <inertia>
            <ixx>0.01</ixx>
            <ixy>0</ixy>
            <ixz>0</ixz>
            <iyy>0.01</iyy>
            <iyz>0</iyz>
            <izz>0.01</izz>
          </inertia>
        </inertial>
        <collision name='link_18_collision'>
          <pose>0.1 0 0 0 1.57079 0</pose>
          <geometry>
            <cylinder>
              <length>0.2</length>
              <radius>0.025</radius>
            </cylinder>
          </geometry>
          <max_contacts>10</max_contacts>
          <surface>
            <contact>
              <ode/>
            </contact>
            <bounce/>
            <friction>
              <torsional>
                <ode/>
              </torsional>
              <ode/>
            </friction>
          </surface>
        </collision>
        <visual name='link_18_vis'>
          <pose>0.1 0 0 0 1.57079 0</pose>
          <geometry>
            <cylinder>
              <length>0.2</length>
              <radius>0.025</radius>
            </cylinder>
          </geometry>
        </visual>
        <velocity_decay/>
        <self_collide>0</self_collide>
        <enable_wind>0</enable_wind>
        <kinematic>0</kinematic>
      </link>
      <joint name='joint_18_2' type='revolute'>
        <child>link_18</child>
        <parent>sphere_18</parent>
        <axis>
          <xyz expressed_in='__model__'>0 1 0</xyz>
          <limit>
            <lower>-0.7</lower>
            <upper>0.7</upper>
          </limit>
          <dynamics>
            <damping>10</damping>
            <friction>0</friction>
            <spring_reference>0</spring_reference>
            <spring_stiffness>0</spring_stiffness>
          </dynamics>
        </axis>
      </joint>
      <link name='sphere_19'>
        <gravity>0</gravity>
        <pose>3.7 0 0 0 -0 0</pose>
        <inertial>
          <pose>0 0 0 0 -0 0</pose>
          <mass>0.1</mass>
          <inertia>
            <ixx>0.01</ixx>
            <ixy>0</ixy>
            <ixz>0</ixz>
            <iyy>0.01</iyy>
            <iyz>0</iyz>
            <izz>0.01</izz>
          </inertia>
        </inertial>
        <collision name='sphere_19_collision'>
          <pose>0 0 0 0 -0 0</pose>
          <geometry>
            <sphere>
              <radius>0.025</radius>
            </sphere>
          </geometry>
          <max_contacts>10</max_contacts>
          <surface>
            <contact>
              <ode/>
            </contact>
            <bounce/>
            <friction>
              <torsional>
                <ode/>
              </torsional>
              <ode/>
            </friction>
          </surface>
        </collision>
        <visual name='sphere_19_vis'>
          <pose>0 0 0 0 -0 0</pose>
          <geometry>
            <sphere>
              <radius>0.025</radius>
            </sphere>
          </geometry>
        </visual>
        <velocity_decay/>
        <self_collide>0</self_collide>
        <enable_wind>0</enable_wind>
        <kinematic>0</kinematic>
      </link>
      <joint name='joint_19_1' type='revolute'>
        <child>sphere_19</child>
        <parent>link_18</parent>
        <axis>
          <xyz expressed_in='__model__'>0 0 1</xyz>
          <limit>
            <lower>-0.7</lower>
            <upper>0.7</upper>
          </limit>
          <dynamics>
            <damping>10</damping>
            <friction>0</friction>
            <spring_reference>0</spring_reference>
            <spring_stiffness>0</spring_stiffness>
          </dynamics>
        </axis>
      </joint>
      <link name='link_19'>
        <gravity>0</gravity>
        <pose>3.7 0 0 0 -0 0</pose>
        <inertial>
          <pose>0 0 0 0 -0 0</pose>
          <mass>0.1</mass>
          <inertia>
            <ixx>0.01</ixx>
            <ixy>0</ixy>
            <ixz>0</ixz>
            <iyy>0.01</iyy>
            <iyz>0</iyz>
            <izz>0.01</izz>
          </inertia>
        </inertial>
        <collision name='link_19_collision'>
          <pose>0.1 0 0 0 1.57079 0</pose>
          <geometry>
            <cylinder>
              <length>0.2</length>
              <radius>0.025</radius>
            </cylinder>
          </geometry>
          <max_contacts>10</max_contacts>
          <surface>
            <contact>
              <ode/>
            </contact>
            <bounce/>
            <friction>
              <torsional>
                <ode/>
              </torsional>
              <ode/>
            </friction>
          </surface>
        </collision>
        <visual name='link_19_vis'>
          <pose>0.1 0 0 0 1.57079 0</pose>
          <geometry>
            <cylinder>
              <length>0.2</length>
              <radius>0.025</radius>
            </cylinder>
          </geometry>
        </visual>
        <velocity_decay/>
        <self_collide>0</self_collide>
        <enable_wind>0</enable_wind>
        <kinematic>0</kinematic>
      </link>
      <joint name='joint_19_2' type='revolute'>
        <child>link_19</child>
        <parent>sphere_19</parent>
        <axis>
          <xyz expressed_in='__model__'>0 1 0</xyz>
          <limit>
            <lower>-0.7</lower>
            <upper>0.7</upper>
          </limit>
          <dynamics>
            <damping>10</damping>
            <friction>0</friction>
            <spring_reference>0</spring_reference>
            <spring_stiffness>0</spring_stiffness>
          </dynamics>
        </axis>
      </joint>
      <link name='sphere_20'>
        <gravity>0</gravity>
        <pose>3.9 0 0 0 -0 0</pose>
        <inertial>
          <pose>0 0 0 0 -0 0</pose>
          <mass>0.1</mass>
          <inertia>
            <ixx>0.01</ixx>
            <ixy>0</ixy>
            <ixz>0</ixz>
            <iyy>0.01</iyy>
            <iyz>0</iyz>
            <izz>0.01</izz>
          </inertia>
        </inertial>
        <collision name='sphere_20_collision'>
          <pose>0 0 0 0 -0 0</pose>
          <geometry>
            <sphere>
              <radius>0.025</radius>
            </sphere>
          </geometry>
          <max_contacts>10</max_contacts>
          <surface>
            <contact>
              <ode/>
            </contact>
            <bounce/>
            <friction>
              <torsional>
                <ode/>
              </torsional>
              <ode/>
            </friction>
          </surface>
        </collision>
        <visual name='sphere_20_vis'>
          <pose>0 0 0 0 -0 0</pose>
          <geometry>
            <sphere>
              <radius>0.025</radius>
            </sphere>
          </geometry>
        </visual>
        <velocity_decay/>
        <self_collide>0</self_collide>
        <enable_wind>0</enable_wind>
        <kinematic>0</kinematic>
      </link>
      <joint name='joint_20_1' type='revolute'>
        <child>sphere_20</child>
        <parent>link_19</parent>
        <axis>
          <xyz expressed_in='__model__'>0 0 1</xyz>
          <limit>
            <lower>-0.7</lower>
            <upper>0.7</upper>
          </limit>
          <dynamics>
            <damping>10</damping>
            <friction>0</friction>
            <spring_reference>0</spring_reference>
            <spring_stiffness>0</spring_stiffness>
          </dynamics>
        </axis>
      </joint>
      <link name='coupling'>
        <pose>3.9 0 0 0 -0 0</pose>
        <inertial>
          <pose>0 0 0 0 -0 0</pose>
          <mass>0.1</mass>
          <inertia>
            <ixx>0.01</ixx>
            <ixy>0</ixy>
            <ixz>0</ixz>
            <iyy>0.01</iyy>
            <iyz>0</iyz>
            <izz>0.01</izz>
          </inertia>
        </inertial>
        <collision name='coupling_collision'>
          <pose>0 0 0 0 -0 0</pose>
          <geometry>
            <mesh>
              <scale>0.001 0.001 0.001</scale>
              <uri>model://fire_hose_long/meshes/coupling.stl</uri>
            </mesh>
          </geometry>
          <max_contacts>10</max_contacts>
          <surface>
            <contact>
              <ode/>
            </contact>
            <bounce/>
            <friction>
              <torsional>
                <ode/>
              </torsional>
              <ode/>
            </friction>
          </surface>
        </collision>
        <visual name='coupling_vis'>
          <pose>0 0 0 0 -0 0</pose>
          <geometry>
            <mesh>
              <scale>0.001 0.001 0.001</scale>
              <uri>model://fire_hose_long/meshes/coupling.stl</uri>
            </mesh>
          </geometry>
        </visual>
        <velocity_decay/>
        <self_collide>0</self_collide>
        <enable_wind>0</enable_wind>
        <kinematic>0</kinematic>
      </link>
      <joint name='joint_20_2' type='revolute'>
        <child>coupling</child>
        <parent>sphere_20</parent>
        <axis>
          <xyz expressed_in='__model__'>0 1 0</xyz>
          <limit>
            <lower>-0.7</lower>
            <upper>0.7</upper>
          </limit>
          <dynamics>
            <damping>10</damping>
            <friction>0</friction>
            <spring_reference>0</spring_reference>
            <spring_stiffness>0</spring_stiffness>
          </dynamics>
        </axis>
      </joint>
    </model>
    <model name='Construction Cone_0'>
      <link name='link'>
        <collision name='collision'>
          <geometry>
            <mesh>
              <scale>10 10 10</scale>
              <uri>model://construction_cone/meshes/construction_cone.dae</uri>
            </mesh>
          </geometry>
          <max_contacts>10</max_contacts>
          <surface>
            <contact>
              <ode/>
            </contact>
            <bounce/>
            <friction>
              <torsional>
                <ode/>
              </torsional>
              <ode/>
            </friction>
          </surface>
        </collision>
        <visual name='visual'>
          <geometry>
            <mesh>
              <scale>10 10 10</scale>
              <uri>model://construction_cone/meshes/construction_cone.dae</uri>
            </mesh>
          </geometry>
        </visual>
        <self_collide>0</self_collide>
        <inertial>
          <pose>0 0 0 0 -0 0</pose>
          <inertia>
            <ixx>1</ixx>
            <ixy>0</ixy>
            <ixz>0</ixz>
            <iyy>1</iyy>
            <iyz>0</iyz>
            <izz>1</izz>
          </inertia>
          <mass>1</mass>
        </inertial>
        <enable_wind>0</enable_wind>
        <kinematic>0</kinematic>
      </link>
      <pose>1.53713 -1.34209 0 0 -0 0</pose>
    </model>
    <model name='Construction Cone'>
      <link name='link'>
        <collision name='collision'>
          <geometry>
            <mesh>
              <scale>10 10 10</scale>
              <uri>model://construction_cone/meshes/construction_cone.dae</uri>
            </mesh>
          </geometry>
          <max_contacts>10</max_contacts>
          <surface>
            <contact>
              <ode/>
            </contact>
            <bounce/>
            <friction>
              <torsional>
                <ode/>
              </torsional>
              <ode/>
            </friction>
          </surface>
        </collision>
        <visual name='visual'>
          <geometry>
            <mesh>
              <scale>10 10 10</scale>
              <uri>model://construction_cone/meshes/construction_cone.dae</uri>
            </mesh>
          </geometry>
        </visual>
        <self_collide>0</self_collide>
        <inertial>
          <pose>0 0 0 0 -0 0</pose>
          <inertia>
            <ixx>1</ixx>
            <ixy>0</ixy>
            <ixz>0</ixz>
            <iyy>1</iyy>
            <iyz>0</iyz>
            <izz>1</izz>
          </inertia>
          <mass>1</mass>
        </inertial>
        <enable_wind>0</enable_wind>
        <kinematic>0</kinematic>
      </link>
      <pose>-1.51887 0.278099 0 0 -0 0</pose>
    </model>
    <model name='Construction Cone_1'>
      <link name='link'>
        <collision name='collision'>
          <geometry>
            <mesh>
              <scale>10 10 10</scale>
              <uri>model://construction_cone/meshes/construction_cone.dae</uri>
            </mesh>
          </geometry>
          <max_contacts>10</max_contacts>
          <surface>
            <contact>
              <ode/>
            </contact>
            <bounce/>
            <friction>
              <torsional>
                <ode/>
              </torsional>
              <ode/>
            </friction>
          </surface>
        </collision>
        <visual name='visual'>
          <geometry>
            <mesh>
              <scale>10 10 10</scale>
              <uri>model://construction_cone/meshes/construction_cone.dae</uri>
            </mesh>
          </geometry>
        </visual>
        <self_collide>0</self_collide>
        <inertial>
          <pose>0 0 0 0 -0 0</pose>
          <inertia>
            <ixx>1</ixx>
            <ixy>0</ixy>
            <ixz>0</ixz>
            <iyy>1</iyy>
            <iyz>0</iyz>
            <izz>1</izz>
          </inertia>
          <mass>1</mass>
        </inertial>
        <enable_wind>0</enable_wind>
        <kinematic>0</kinematic>
      </link>
      <pose>2.0035 1.19456 0 0 -0 0</pose>
    </model>
    <model name='Construction Cone_2'>
      <link name='link'>
        <collision name='collision'>
          <geometry>
            <mesh>
              <scale>10 10 10</scale>
              <uri>model://construction_cone/meshes/construction_cone.dae</uri>
            </mesh>
          </geometry>
          <max_contacts>10</max_contacts>
          <surface>
            <contact>
              <ode/>
            </contact>
            <bounce/>
            <friction>
              <torsional>
                <ode/>
              </torsional>
              <ode/>
            </friction>
          </surface>
        </collision>
        <visual name='visual'>
          <geometry>
            <mesh>
              <scale>10 10 10</scale>
              <uri>model://construction_cone/meshes/construction_cone.dae</uri>
            </mesh>
          </geometry>
        </visual>
        <self_collide>0</self_collide>
        <inertial>
          <pose>0 0 0 0 -0 0</pose>
          <inertia>
            <ixx>1</ixx>
            <ixy>0</ixy>
            <ixz>0</ixz>
            <iyy>1</iyy>
            <iyz>0</iyz>
            <izz>1</izz>
          </inertia>
          <mass>1</mass>
        </inertial>
        <enable_wind>0</enable_wind>
        <kinematic>0</kinematic>
      </link>
      <pose>-0.458848 -2.44897 0 0 -0 0</pose>
    </model>
    <model name='Construction Cone_3'>
      <link name='link'>
        <collision name='collision'>
          <geometry>
            <mesh>
              <scale>10 10 10</scale>
              <uri>model://construction_cone/meshes/construction_cone.dae</uri>
            </mesh>
          </geometry>
          <max_contacts>10</max_contacts>
          <surface>
            <contact>
              <ode/>
            </contact>
            <bounce/>
            <friction>
              <torsional>
                <ode/>
              </torsional>
              <ode/>
            </friction>
          </surface>
        </collision>
        <visual name='visual'>
          <geometry>
            <mesh>
              <scale>10 10 10</scale>
              <uri>model://construction_cone/meshes/construction_cone.dae</uri>
            </mesh>
          </geometry>
        </visual>
        <self_collide>0</self_collide>
        <inertial>
          <pose>0 0 0 0 -0 0</pose>
          <inertia>
            <ixx>1</ixx>
            <ixy>0</ixy>
            <ixz>0</ixz>
            <iyy>1</iyy>
            <iyz>0</iyz>
            <izz>1</izz>
          </inertia>
          <mass>1</mass>
        </inertial>
        <enable_wind>0</enable_wind>
        <kinematic>0</kinematic>
      </link>
      <pose>-0.535667 2.17511 0 0 -0 0</pose>
    </model>
    <model name='Construction Cone_4'>
      <link name='link'>
        <collision name='collision'>
          <geometry>
            <mesh>
              <scale>10 10 10</scale>
              <uri>model://construction_cone/meshes/construction_cone.dae</uri>
            </mesh>
          </geometry>
          <max_contacts>10</max_contacts>
          <surface>
            <contact>
              <ode/>
            </contact>
            <bounce/>
            <friction>
              <torsional>
                <ode/>
              </torsional>
              <ode/>
            </friction>
          </surface>
        </collision>
        <visual name='visual'>
          <geometry>
            <mesh>
              <scale>10 10 10</scale>
              <uri>model://construction_cone/meshes/construction_cone.dae</uri>
            </mesh>
          </geometry>
        </visual>
        <self_collide>0</self_collide>
        <inertial>
          <pose>0 0 0 0 -0 0</pose>
          <inertia>
            <ixx>1</ixx>
            <ixy>0</ixy>
            <ixz>0</ixz>
            <iyy>1</iyy>
            <iyz>0</iyz>
            <izz>1</izz>
          </inertia>
          <mass>1</mass>
        </inertial>
        <enable_wind>0</enable_wind>
        <kinematic>0</kinematic>
      </link>
      <pose>-2.97754 1.99969 0 0 -0 0</pose>
    </model>
    <model name='Construction Cone_5'>
      <link name='link'>
        <collision name='collision'>
          <geometry>
            <mesh>
              <scale>10 10 10</scale>
              <uri>model://construction_cone/meshes/construction_cone.dae</uri>
            </mesh>
          </geometry>
          <max_contacts>10</max_contacts>
          <surface>
            <contact>
              <ode/>
            </contact>
            <bounce/>
            <friction>
              <torsional>
                <ode/>
              </torsional>
              <ode/>
            </friction>
          </surface>
        </collision>
        <visual name='visual'>
          <geometry>
            <mesh>
              <scale>10 10 10</scale>
              <uri>model://construction_cone/meshes/construction_cone.dae</uri>
            </mesh>
          </geometry>
        </visual>
        <self_collide>0</self_collide>
        <inertial>
          <pose>0 0 0 0 -0 0</pose>
          <inertia>
            <ixx>1</ixx>
            <ixy>0</ixy>
            <ixz>0</ixz>
            <iyy>1</iyy>
            <iyz>0</iyz>
            <izz>1</izz>
          </inertia>
          <mass>1</mass>
        </inertial>
        <enable_wind>0</enable_wind>
        <kinematic>0</kinematic>
      </link>
      <pose>-2.58269 -1.29797 0 0 -0 0</pose>
    </model>
    <model name='Construction Cone_6'>
      <link name='link'>
        <collision name='collision'>
          <geometry>
            <mesh>
              <scale>10 10 10</scale>
              <uri>model://construction_cone/meshes/construction_cone.dae</uri>
            </mesh>
          </geometry>
          <max_contacts>10</max_contacts>
          <surface>
            <contact>
              <ode/>
            </contact>
            <bounce/>
            <friction>
              <torsional>
                <ode/>
              </torsional>
              <ode/>
            </friction>
          </surface>
        </collision>
        <visual name='visual'>
          <geometry>
            <mesh>
              <scale>10 10 10</scale>
              <uri>model://construction_cone/meshes/construction_cone.dae</uri>
            </mesh>
          </geometry>
        </visual>
        <self_collide>0</self_collide>
        <inertial>
          <pose>0 0 0 0 -0 0</pose>
          <inertia>
            <ixx>1</ixx>
            <ixy>0</ixy>
            <ixz>0</ixz>
            <iyy>1</iyy>
            <iyz>0</iyz>
            <izz>1</izz>
          </inertia>
          <mass>1</mass>
        </inertial>
        <enable_wind>0</enable_wind>
        <kinematic>0</kinematic>
      </link>
      <pose>3.66314 -0.136933 0 0 -0 0</pose>
    </model>
    <model name='Construction Cone_7'>
      <link name='link'>
        <collision name='collision'>
          <geometry>
            <mesh>
              <scale>10 10 10</scale>
              <uri>model://construction_cone/meshes/construction_cone.dae</uri>
            </mesh>
          </geometry>
          <max_contacts>10</max_contacts>
          <surface>
            <contact>
              <ode/>
            </contact>
            <bounce/>
            <friction>
              <torsional>
                <ode/>
              </torsional>
              <ode/>
            </friction>
          </surface>
        </collision>
        <visual name='visual'>
          <geometry>
            <mesh>
              <scale>10 10 10</scale>
              <uri>model://construction_cone/meshes/construction_cone.dae</uri>
            </mesh>
          </geometry>
        </visual>
        <self_collide>0</self_collide>
        <inertial>
          <pose>0 0 0 0 -0 0</pose>
          <inertia>
            <ixx>1</ixx>
            <ixy>0</ixy>
            <ixz>0</ixz>
            <iyy>1</iyy>
            <iyz>0</iyz>
            <izz>1</izz>
          </inertia>
          <mass>1</mass>
        </inertial>
        <enable_wind>0</enable_wind>
        <kinematic>0</kinematic>
      </link>
      <pose>1.37095 2.83892 0 0 -0 0</pose>
    </model>
    <model name='Construction Cone_8'>
      <link name='link'>
        <collision name='collision'>
          <geometry>
            <mesh>
              <scale>10 10 10</scale>
              <uri>model://construction_cone/meshes/construction_cone.dae</uri>
            </mesh>
          </geometry>
          <max_contacts>10</max_contacts>
          <surface>
            <contact>
              <ode/>
            </contact>
            <bounce/>
            <friction>
              <torsional>
                <ode/>
              </torsional>
              <ode/>
            </friction>
          </surface>
        </collision>
        <visual name='visual'>
          <geometry>
            <mesh>
              <scale>10 10 10</scale>
              <uri>model://construction_cone/meshes/construction_cone.dae</uri>
            </mesh>
          </geometry>
        </visual>
        <self_collide>0</self_collide>
        <inertial>
          <pose>0 0 0 0 -0 0</pose>
          <inertia>
            <ixx>1</ixx>
            <ixy>0</ixy>
            <ixz>0</ixz>
            <iyy>1</iyy>
            <iyz>0</iyz>
            <izz>1</izz>
          </inertia>
          <mass>1</mass>
        </inertial>
        <enable_wind>0</enable_wind>
        <kinematic>0</kinematic>
      </link>
      <pose>-1.55083 -2.47941 0 0 -0 0</pose>
    </model>
    <state world_name='default'>
      <sim_time>1112 112000000</sim_time>
      <real_time>1123 178642043</real_time>
      <wall_time>1749872188 635273348</wall_time>
      <iterations>1112112</iterations>
      <model name='Construction Cone'>
        <pose>-1.51887 0.278099 -0 0 -1e-06 0</pose>
        <scale>1 1 1</scale>
        <link name='link'>
          <pose>-1.51887 0.278099 -0 0 -1e-06 0</pose>
          <velocity>0 0 0 0 -0 0</velocity>
          <acceleration>-0 0 0.008512 2.58585 -1.13682 -3.14159</acceleration>
          <wrench>-0 0 0.008512 0 -0 0</wrench>
        </link>
      </model>
      <model name='Construction Cone_0'>
        <pose>1.53713 -1.34209 -0 0 -1e-06 0</pose>
        <scale>1 1 1</scale>
        <link name='link'>
          <pose>1.53713 -1.34209 -0 0 -1e-06 0</pose>
          <velocity>0 0 0 0 -0 0</velocity>
          <acceleration>-0 0 0.008512 2.58585 -1.13682 -3.14159</acceleration>
          <wrench>-0 0 0.008512 0 -0 0</wrench>
        </link>
      </model>
      <model name='Construction Cone_1'>
        <pose>2.0035 1.19456 -0 0 -0 0</pose>
        <scale>1 1 1</scale>
        <link name='link'>
          <pose>2.0035 1.19456 -0 0 -0 0</pose>
          <velocity>0 0 0 0 -0 0</velocity>
          <acceleration>0 -0 -0.008512 -2.58585 1.13682 3.14159</acceleration>
          <wrench>0 -0 -0.008512 0 -0 0</wrench>
        </link>
      </model>
      <model name='Construction Cone_2'>
        <pose>-0.458848 -2.44897 -0 1e-06 -0 0</pose>
        <scale>1 1 1</scale>
        <link name='link'>
          <pose>-0.458848 -2.44897 -0 1e-06 -0 0</pose>
          <velocity>0 0 0 0 -0 0</velocity>
          <acceleration>-0 -0 -9.79991 2.4e-05 1.6e-05 0</acceleration>
          <wrench>-0 -0 -9.79991 0 -0 0</wrench>
        </link>
      </model>
      <model name='Construction Cone_3'>
        <pose>-0.535667 2.17511 -0 0 -0 0</pose>
        <scale>1 1 1</scale>
        <link name='link'>
          <pose>-0.535667 2.17511 -0 0 -0 0</pose>
          <velocity>0 0 0 0 -0 0</velocity>
          <acceleration>0 -0 -0.008512 -2.58585 1.13682 3.14159</acceleration>
          <wrench>0 -0 -0.008512 0 -0 0</wrench>
        </link>
      </model>
      <model name='Construction Cone_4'>
        <pose>-2.97754 1.99969 -0 0 -0 0</pose>
        <scale>1 1 1</scale>
        <link name='link'>
          <pose>-2.97754 1.99969 -0 0 -0 0</pose>
          <velocity>0 0 0 0 -0 0</velocity>
          <acceleration>0 -0 -0.008512 -2.58585 1.13682 3.14159</acceleration>
          <wrench>0 -0 -0.008512 0 -0 0</wrench>
        </link>
      </model>
      <model name='Construction Cone_5'>
        <pose>-2.58269 -1.29797 -8e-06 0 1e-06 0</pose>
        <scale>1 1 1</scale>
        <link name='link'>
          <pose>-2.58269 -1.29797 -8e-06 0 1e-06 0</pose>
          <velocity>0 0 0 0 -0 0</velocity>
          <acceleration>0 0 -9.8 0 -0 0</acceleration>
          <wrench>0 0 -9.8 0 -0 0</wrench>
        </link>
      </model>
      <model name='Construction Cone_6'>
        <pose>3.66314 -0.136933 -0 0 -1e-06 0</pose>
        <scale>1 1 1</scale>
        <link name='link'>
          <pose>3.66314 -0.136933 -0 0 -1e-06 0</pose>
          <velocity>0 0 0 0 -0 0</velocity>
          <acceleration>-0 0 0.008512 2.58585 -1.13682 -3.14159</acceleration>
          <wrench>-0 0 0.008512 0 -0 0</wrench>
        </link>
      </model>
      <model name='Construction Cone_7'>
        <pose>1.37095 2.83892 -0 0 -0 0</pose>
        <scale>1 1 1</scale>
        <link name='link'>
          <pose>1.37095 2.83892 -0 0 -0 0</pose>
          <velocity>0 0 0 0 -0 0</velocity>
          <acceleration>0 -0 -0.008512 -2.58585 1.13682 3.14159</acceleration>
          <wrench>0 -0 -0.008512 0 -0 0</wrench>
        </link>
      </model>
      <model name='Construction Cone_8'>
        <pose>-1.55083 -2.47941 -0 0 -1e-06 0</pose>
        <scale>1 1 1</scale>
        <link name='link'>
          <pose>-1.55083 -2.47941 -0 0 -1e-06 0</pose>
          <velocity>0 0 0 0 -0 0</velocity>
          <acceleration>-0 0 0.008512 2.58585 -1.13682 -3.14159</acceleration>
          <wrench>-0 0 0.008512 0 -0 0</wrench>
        </link>
      </model>
      <model name='fire_hose_long'>
        <pose>0.523019 0.062878 10 1.23283 0.318678 0.720963</pose>
        <scale>1 1 1</scale>
        <link name='coupling'>
          <pose>0.643572 0.209514 6.1936 -2.31244 1.57079 -2.86237</pose>
          <velocity>-1.1e-05 1.2e-05 -1e-06 0 -0 5.4e-05</velocity>
          <acceleration>0 -0 0 0 -0 0</acceleration>
          <wrench>0 -0 0 0 -0 0</wrench>
        </link>
        <link name='link_01'>
          <pose>0.594354 0.125565 9.96867 1.59337 1.06612 1.04066</pose>
          <velocity>-1.4e-05 1.4e-05 -3e-06 -1e-06 -3.6e-05 5.4e-05</velocity>
          <acceleration>0 -0 0 0 -0 0</acceleration>
          <wrench>0 -0 0 0 -0 0</wrench>
        </link>
        <link name='link_02'>
          <pose>0.643253 0.208997 9.7936 1.87368 1.56393 1.32372</pose>
          <velocity>-1.2e-05 1.7e-05 -1e-06 -5.1e-05 -4e-06 5.5e-05</velocity>
          <acceleration>0 -0 0 0 -0 0</acceleration>
          <wrench>0 -0 0 0 -0 0</wrench>
        </link>
        <link name='link_03'>
          <pose>0.643589 0.210328 9.59361 -1.15151 1.56546 -1.70145</pose>
          <velocity>-1.1e-05 7e-06 -1e-06 2.8e-05 -6e-06 5.4e-05</velocity>
          <acceleration>0 -0 0 0 -0 0</acceleration>
          <wrench>0 -0 0 0 -0 0</wrench>
        </link>
        <link name='link_04'>
          <pose>0.643449 0.209269 9.39361 1.28457 1.56968 0.734638</pose>
          <velocity>-1e-05 1.2e-05 -1e-06 4e-06 6e-06 5.4e-05</velocity>
          <acceleration>0 -0 0 -0 -0 -0</acceleration>
          <wrench>0 -0 0 0 -0 0</wrench>
        </link>
        <link name='link_05'>
          <pose>0.643615 0.209418 9.19361 2.15401 1.57015 1.60407</pose>
          <velocity>-1.1e-05 1.3e-05 -1e-06 -5e-06 2e-06 5.4e-05</velocity>
          <acceleration>0 -0 0 0 -0 0</acceleration>
          <wrench>0 -0 0 0 -0 0</wrench>
        </link>
        <link name='link_06'>
          <pose>0.643611 0.209547 8.99361 -2.42488 1.57059 -2.97481</pose>
          <velocity>-1.2e-05 1.2e-05 -1e-06 -2e-06 -1e-06 5.4e-05</velocity>
          <acceleration>0 -0 0 0 -0 0</acceleration>
          <wrench>0 -0 0 0 -0 0</wrench>
        </link>
        <link name='link_07'>
          <pose>0.64357 0.20954 8.79361 -1.35972 1.57066 -1.90966</pose>
          <velocity>-1.1e-05 1.2e-05 -1e-06 1e-06 -1e-06 5.4e-05</velocity>
          <acceleration>0 -0 0 0 -0 0</acceleration>
          <wrench>0 -0 0 0 -0 0</wrench>
        </link>
        <link name='link_08'>
          <pose>0.643561 0.209515 8.59361 -0.165911 1.57075 -0.715843</pose>
          <velocity>-1.1e-05 1.2e-05 -1e-06 1e-06 0 5.4e-05</velocity>
          <acceleration>0 -0 0 0 -0 0</acceleration>
          <wrench>0 -0 0 0 -0 0</wrench>
        </link>
        <link name='link_09'>
          <pose>0.643569 0.209508 8.39361 1.05175 1.57076 0.501815</pose>
          <velocity>-1.1e-05 1.2e-05 -1e-06 0 -0 5.4e-05</velocity>
          <acceleration>0 -0 0 -0 -0 -0</acceleration>
          <wrench>0 -0 0 0 -0 0</wrench>
        </link>
        <link name='link_10'>
          <pose>0.643574 0.209511 8.1936 1.94612 1.57078 1.39619</pose>
          <velocity>-1.1e-05 1.2e-05 -1e-06 0 -0 5.4e-05</velocity>
          <acceleration>0 -0 0 -0 -0 -0</acceleration>
          <wrench>0 -0 0 0 -0 0</wrench>
        </link>
        <link name='link_11'>
          <pose>0.643575 0.209515 7.9936 -3.05761 1.57079 2.67564</pose>
          <velocity>-1.1e-05 1.2e-05 -1e-06 0 -0 5.4e-05</velocity>
          <acceleration>0 -0 0 0 -0 0</acceleration>
          <wrench>0 -0 0 0 -0 0</wrench>
        </link>
        <link name='link_12'>
          <pose>0.643573 0.209515 7.7936 -2.21829 1.57079 -2.76822</pose>
          <velocity>-1.1e-05 1.2e-05 -1e-06 0 -0 5.4e-05</velocity>
          <acceleration>0 -0 0 0 -0 0</acceleration>
          <wrench>0 -0 0 0 -0 0</wrench>
        </link>
        <link name='link_13'>
          <pose>0.643572 0.209515 7.5936 -1.37496 1.57079 -1.92489</pose>
          <velocity>-1.1e-05 1.2e-05 -1e-06 0 -0 5.4e-05</velocity>
          <acceleration>0 -0 0 0 -0 0</acceleration>
          <wrench>0 -0 0 0 -0 0</wrench>
        </link>
        <link name='link_14'>
          <pose>0.643572 0.209514 7.3936 0.26452 1.57079 -0.285413</pose>
          <velocity>-1.1e-05 1.2e-05 -1e-06 0 -0 5.4e-05</velocity>
          <acceleration>0 -0 0 0 -0 0</acceleration>
          <wrench>0 -0 0 0 -0 0</wrench>
        </link>
        <link name='link_15'>
          <pose>0.643572 0.209514 7.1936 0.794206 1.57079 0.244274</pose>
          <velocity>-1.1e-05 1.2e-05 -1e-06 0 -0 5.4e-05</velocity>
          <acceleration>0 -0 0 0 -0 0</acceleration>
          <wrench>0 -0 0 0 -0 0</wrench>
        </link>
        <link name='link_16'>
          <pose>0.643573 0.209514 6.9936 -2.45612 1.57079 -3.00605</pose>
          <velocity>-1.1e-05 1.2e-05 -1e-06 0 -0 5.4e-05</velocity>
          <acceleration>0 -0 0 0 -0 0</acceleration>
          <wrench>0 -0 0 0 -0 0</wrench>
        </link>
        <link name='link_17'>
          <pose>0.643572 0.209514 6.7936 -2.44025 1.57079 -2.99018</pose>
          <velocity>-1.1e-05 1.2e-05 -1e-06 0 -0 5.4e-05</velocity>
          <acceleration>0 -0 0 0 -0 0</acceleration>
          <wrench>0 -0 0 0 -0 0</wrench>
        </link>
        <link name='link_18'>
          <pose>0.643572 0.209514 6.5936 0.833235 1.57079 0.283302</pose>
          <velocity>-1.1e-05 1.2e-05 -1e-06 0 -0 5.4e-05</velocity>
          <acceleration>0 -0 0 0 -0 0</acceleration>
          <wrench>0 -0 0 0 -0 0</wrench>
        </link>
        <link name='link_19'>
          <pose>0.643574 0.209515 6.3936 -2.31099 1.57079 -2.86092</pose>
          <velocity>-1.1e-05 1.2e-05 -1e-06 0 -0 5.4e-05</velocity>
          <acceleration>0 -0 0 0 -0 0</acceleration>
          <wrench>0 -0 0 0 -0 0</wrench>
        </link>
        <link name='nozzle'>
          <pose>0.523019 0.062878 10 1.23283 0.318678 0.720963</pose>
          <velocity>0 -0 0 9.8e-05 0.000124 0.000157</velocity>
          <acceleration>-0 0 -0 0 -1e-06 -1e-06</acceleration>
          <wrench>-0 0 -0 0 -0 0</wrench>
        </link>
        <link name='sphere_01'>
          <pose>0.594354 0.125565 9.96867 0.993458 0.955856 0.341681</pose>
          <velocity>-1.4e-05 1.4e-05 -3e-06 9.8e-05 0.000124 0.000157</velocity>
          <acceleration>0 -0 0 0 -1e-06 -1e-06</acceleration>
          <wrench>0 -0 0 0 -0 0</wrench>
        </link>
        <link name='sphere_02'>
          <pose>0.643253 0.208997 9.7936 2.601 1.55807 2.05106</pose>
          <velocity>-1.2e-05 1.7e-05 -1e-06 -5.2e-05 -4e-06 5.5e-05</velocity>
          <acceleration>0 -0 0 0 -0 0</acceleration>
          <wrench>0 -0 0 0 -0 0</wrench>
        </link>
        <link name='sphere_03'>
          <pose>0.643589 0.210328 9.59361 -1.96822 1.56551 -2.51817</pose>
          <velocity>-1.1e-05 7e-06 -1e-06 7e-06 -4e-05 5.4e-05</velocity>
          <acceleration>0 -0 0 0 -0 0</acceleration>
          <wrench>0 -0 0 0 -0 0</wrench>
        </link>
        <link name='sphere_04'>
          <pose>0.643449 0.209269 9.39361 0.457123 1.56837 -0.09281</pose>
          <velocity>-1e-05 1.2e-05 -1e-06 5e-06 8e-06 5.4e-05</velocity>
          <acceleration>0 -0 0 0 -0 0</acceleration>
          <wrench>0 -0 0 0 -0 0</wrench>
        </link>
        <link name='sphere_05'>
          <pose>0.643615 0.209418 9.19361 1.04126 1.57017 0.491324</pose>
          <velocity>-1.1e-05 1.3e-05 -1e-06 -1e-06 9e-06 5.4e-05</velocity>
          <acceleration>0 -0 0 -0 -0 -0</acceleration>
          <wrench>0 -0 0 0 -0 0</wrench>
        </link>
        <link name='sphere_06'>
          <pose>0.643611 0.209547 8.99361 -2.77608 1.57042 2.95717</pose>
          <velocity>-1.2e-05 1.2e-05 -1e-06 -1e-06 -0 5.4e-05</velocity>
          <acceleration>0 -0 0 0 -0 0</acceleration>
          <wrench>0 -0 0 0 -0 0</wrench>
        </link>
        <link name='sphere_07'>
          <pose>0.64357 0.20954 8.79361 -2.44361 1.57059 -2.99355</pose>
          <velocity>-1.1e-05 1.2e-05 -1e-06 0 -3e-06 5.4e-05</velocity>
          <acceleration>0 -0 0 0 -0 0</acceleration>
          <wrench>0 -0 0 0 -0 0</wrench>
        </link>
        <link name='sphere_08'>
          <pose>0.643561 0.209515 8.59361 -0.290024 1.57077 -0.839956</pose>
          <velocity>-1.1e-05 1.2e-05 -1e-06 0 -1e-06 5.4e-05</velocity>
          <acceleration>0 -0 0 0 -0 0</acceleration>
          <wrench>0 -0 0 0 -0 0</wrench>
        </link>
        <link name='sphere_09'>
          <pose>0.643569 0.209508 8.39361 0.512575 1.57074 -0.037357</pose>
          <velocity>-1.1e-05 1.2e-05 -1e-06 0 -0 5.4e-05</velocity>
          <acceleration>0 -0 0 0 -0 0</acceleration>
          <wrench>0 -0 0 0 -0 0</wrench>
        </link>
        <link name='sphere_10'>
          <pose>0.643574 0.209511 8.1936 0.728657 1.57078 0.178725</pose>
          <velocity>-1.1e-05 1.2e-05 -1e-06 0 -0 5.4e-05</velocity>
          <acceleration>0 -0 0 -0 -0 -0</acceleration>
          <wrench>0 -0 0 0 -0 0</wrench>
        </link>
        <link name='sphere_11'>
          <pose>0.643575 0.209515 7.9936 -3.02115 1.57079 2.7121</pose>
          <velocity>-1.1e-05 1.2e-05 -1e-06 0 -0 5.4e-05</velocity>
          <acceleration>0 -0 0 -0 -0 -0</acceleration>
          <wrench>0 -0 0 0 -0 0</wrench>
        </link>
        <link name='sphere_12'>
          <pose>0.643573 0.209515 7.7936 -2.63473 1.57079 3.09852</pose>
          <velocity>-1.1e-05 1.2e-05 -1e-06 0 -0 5.4e-05</velocity>
          <acceleration>0 -0 0 0 -0 0</acceleration>
          <wrench>0 -0 0 0 -0 0</wrench>
        </link>
        <link name='sphere_13'>
          <pose>0.643572 0.209515 7.5936 -2.56528 1.57079 -3.11521</pose>
          <velocity>-1.1e-05 1.2e-05 -1e-06 0 -0 5.4e-05</velocity>
          <acceleration>0 -0 0 0 -0 0</acceleration>
          <wrench>0 -0 0 0 -0 0</wrench>
        </link>
        <link name='sphere_14'>
          <pose>0.643572 0.209514 7.3936 -2.32534 1.57079 -2.87527</pose>
          <velocity>-1.1e-05 1.2e-05 -1e-06 0 -0 5.4e-05</velocity>
          <acceleration>0 -0 0 0 -0 0</acceleration>
          <wrench>0 -0 0 0 -0 0</wrench>
        </link>
        <link name='sphere_15'>
          <pose>0.643572 0.209514 7.1936 0.448201 1.57079 -0.101731</pose>
          <velocity>-1.1e-05 1.2e-05 -1e-06 0 -0 5.4e-05</velocity>
          <acceleration>0 -0 0 0 -0 0</acceleration>
          <wrench>0 -0 0 0 -0 0</wrench>
        </link>
        <link name='sphere_16'>
          <pose>0.643573 0.209514 6.9936 -1.05052 1.57079 -1.60045</pose>
          <velocity>-1.1e-05 1.2e-05 -1e-06 0 -0 5.4e-05</velocity>
          <acceleration>0 -0 0 0 -0 0</acceleration>
          <wrench>0 -0 0 0 -0 0</wrench>
        </link>
        <link name='sphere_17'>
          <pose>0.643572 0.209514 6.7936 -2.46185 1.57079 -3.01179</pose>
          <velocity>-1.1e-05 1.2e-05 -1e-06 0 -0 5.4e-05</velocity>
          <acceleration>0 -0 0 0 -0 0</acceleration>
          <wrench>0 -0 0 0 -0 0</wrench>
        </link>
        <link name='sphere_18'>
          <pose>0.643572 0.209514 6.5936 1.76649 1.57079 1.21656</pose>
          <velocity>-1.1e-05 1.2e-05 -1e-06 0 -0 5.4e-05</velocity>
          <acceleration>0 -0 0 0 -0 0</acceleration>
          <wrench>0 -0 0 0 -0 0</wrench>
        </link>
        <link name='sphere_19'>
          <pose>0.643574 0.209515 6.3936 -0.648264 1.57079 -1.1982</pose>
          <velocity>-1.1e-05 1.2e-05 -1e-06 0 -0 5.4e-05</velocity>
          <acceleration>0 -0 0 -0 -0 -0</acceleration>
          <wrench>0 -0 0 0 -0 0</wrench>
        </link>
        <link name='sphere_20'>
          <pose>0.643572 0.209514 6.1936 -2.31243 1.57079 -2.86236</pose>
          <velocity>-1.1e-05 1.2e-05 -1e-06 0 -0 5.4e-05</velocity>
          <acceleration>0 -0 0 0 -0 0</acceleration>
          <wrench>0 -0 0 0 -0 0</wrench>
        </link>
      </model>
      <model name='ground_plane'>
        <pose>0 0 0 0 -0 0</pose>
        <scale>1 1 1</scale>
        <link name='link'>
          <pose>0 0 0 0 -0 0</pose>
          <velocity>0 0 0 0 -0 0</velocity>
          <acceleration>0 0 0 0 -0 0</acceleration>
          <wrench>0 0 0 0 -0 0</wrench>
        </link>
      </model>
      <light name='sun'>
        <pose>0 0 10 0 -0 0</pose>
      </light>
    </state>
    <gui fullscreen='0'>
      <camera name='user_camera'>
        <pose>-5.31783 -6.65891 8.24673 0 0.709908 0.99981</pose>
        <view_controller>orbit</view_controller>
        <projection_type>perspective</projection_type>
      </camera>
    </gui>
  </world>
</sdf>
